Workbook

Sheet README
A1: SUPERSEDED - JULY PITCH FIGURES ON THIS SHEET ARE WRONG. DO NOT QUOTE.
A2: Audit 03/08/26: the offer regex had no word boundary, so 'our booking platform' also matched 'y-our booking platform'. Reps saying "YOUR booking platform" (the customer's existing system) were counted as Zoca pitches - 55% false positives on a 22-call sample. Counting was also per Chargebee customer record, and 89 emails map to multiple records. CORRECTED: 63 accounts pitched (not 98); 8 reached scheduling enabled (not 15); 12.7% conversion (not 15%).
A3: UNAFFECTED: adoption funnel (444 locations, 368 enabled, 147 booking in 30d), payments ($645,568 / 139 accounts), cohort retention and migration sources use no regex and stand as published.
A4: Scheduling — pitch, conversion and non-conversion
A7: Prepared | B7: 03/08/26
A8: Question | B8: How many accounts was scheduling pitched to, how many converted, and why did the rest not?
A9: Primary source | B9: Aurora (Postgres) via Metabase database 7 — scheduling.*, chargebee.*, sales.fireflies_meeting, cx.*
A10: Pitch window analysed | B10: 01/07/26 - 31/07/26 (July 2026)
A11: Adoption window analysed | B11: 30/01/26 - 31/07/26 (full scheduling rollout to date)
A13: HEADLINE
A14: Accounts pitched in July 2026 | B14: 98
A15: Of those, reached 'scheduling enabled' | B15: 15 (15%)
A16: Of those, never started onboarding | B16: 76 (78%)
A17: Value processed through scheduling to date | B17: $645,568 across 139 accounts
A19: HOW 'PITCHED' WAS DERIVED
A20: 1 | B20: No system records the pitch as a field. It was reconstructed from call transcripts.
A21: 2 | B21: All 1,051 July calls in sales.fireflies_meeting; 1,046 carry a transcript.
A22: 3 | B22: Attendee emails extracted from 'participants' by regex (field is inconsistently formatted - some JSON arrays, some comma-separated strings, so a JSON cast fails).
A23: 4 | B23: Internal domains dropped: zoca.com, timelyai.com, zoca.ai.
A24: 5 | B24: Remaining emails joined to chargebee.customers.email to identify the account.
A25: 6 | B25: A call counts as an OFFER if the transcript contains Zoca offering its own scheduling ('our own booking platform', 'we have launched', 'comes with a booking platform', 'no extra charges', 'included in your subscription', 'show you our scheduling platform').
A26: 7 | B26: Accounts already live on Zoca scheduling before the call are SUBTRACTED - offer language to an existing user is support, not a pitch. This step removes 12 accounts. Without it the answer is 110 and it is wrong.
A27: 8 | B27: The regex was written only after all 141 candidate excerpts were read by hand; it formalises that read.
A29: COVERAGE LIMITS - READ BEFORE QUOTING
A30: 98 is a floor, not a ceiling | B30: Only accounts whose attendee email matched a Chargebee customer record are counted. 230 of 433 distinct external emails matched (53%).
A31: Prospects excluded | B31: ~84 further external emails were pitched but match no Chargebee customer. Those are new-business pitches, not upsells to the existing book.
A32: Repeat pitching | B32: 284 individual July calls carried offer language against 98 accounts - roughly 2.9 offer-bearing calls per account.
A33: Attribution is temporal, not causal | B33: An onboarding record created after the call is attributed to the pitch. Reasonable in a one-month window; not proven.
A34: Locations vs accounts | B34: The adoption funnel counts 444 LOCATIONS. Only 156 map to an active billed account. Never quote 444 as an account count.
A36: SCHEMA TRAP
A37: Join key | B37: scheduling.onboarding.entity_id matches NOTHING - zero overlap with bookings or Chargebee. The account key is location_entity_id. A join on entity_id returns a valid-looking all-zero result rather than an error.
A39: SHEET GUIDE
A40: Summary | B40: Headline metrics, calculated live from the data sheets
A41: July Pitch Funnel | B41: 1,051 calls narrowed to 98 pitched accounts, stage by stage
A42: Pitched Accounts | B42: Account-level detail: 110 rows = 98 pitched + 12 already-live (flagged in column J)
A43: Adoption Funnel | B43: All 444 onboarding locations, stage by stage
A44: Locations | B44: Account-level detail for all 444 locations
A45: Cohort Retention | B45: Monthly cohorts and how many are still taking bookings
A46: Bookings and Revenue | B46: Booking mix, payments processed, incumbent systems migrated from
A47: Objection Themes | B47: Topic prevalence across 1,829 scheduling calls (Nov 25 - Aug 26)
...

Sheet Summary
A1: SUPERSEDED - JULY PITCH FIGURES ON THIS SHEET ARE WRONG. DO NOT QUOTE.
A2: Audit 03/08/26: the offer regex had no word boundary, so 'our booking platform' also matched 'y-our booking platform'. Reps saying "YOUR booking platform" (the customer's existing system) were counted as Zoca pitches - 55% false positives on a 22-call sample. Counting was also per Chargebee customer record, and 89 emails map to multiple records. CORRECTED: 63 accounts pitched (not 98); 8 reached scheduling enabled (not 15); 12.7% conversion (not 15%).
A3: UNAFFECTED: adoption funnel (444 locations, 368 enabled, 147 booking in 30d), payments ($645,568 / 139 accounts), cohort retention and migration sources use no regex and stand as published.
A4: Summary — scheduling pitch and adoption
A6: As-of date (drives the 30-day activity tests) | B6: =DATE(2026,8,3) | C6: Blue = input. Change this to re-date every 30-day metric in the workbook.
A8: JULY 2026 PITCH | B8: Value | C8: Notes
A9: Accounts pitched | B9: =SUMPRODUCT(--('Pitched Accounts'!$J$2:$J$111=FALSE)) | C9: Offer made and not already live on Zoca scheduling
A10: …that started onboarding | B10: =SUMPRODUCT(--('Pitched Accounts'!$J$2:$J$111=FALSE),--('Pitched Accounts'!$K$2:$K$111<>"")) | C10: Onboarding record created after the call
A11: …that reached scheduling enabled | B11: =SUMPRODUCT(--('Pitched Accounts'!$J$2:$J$111=FALSE),--('Pitched Accounts'!$N$2:$N$111=TRUE)) | C11: The conversion number
A12: …that never started | B12: =SUMPRODUCT(--('Pitched Accounts'!$J$2:$J$111=FALSE),--('Pitched Accounts'!$K$2:$K$111=""))
A13: Pitch-to-activation rate | B13: =B8/B6 | C13: Enabled ÷ pitched
A14: Accounts excluded (already live at pitch) | B14: =SUMPRODUCT(--('Pitched Accounts'!$J$2:$J$111=TRUE)) | C14: Offer language spoken to an existing user = support
A15: Offer-bearing calls in July | B15: 284 | C15: Hardcoded. Source: count of July transcripts matching the offer regex.
A17: ADOPTION TO DATE (444 LOCATIONS) | B17: Value | C17: Notes
A18: Locations entered onboarding | B18: =COUNTA(Locations!$A$2:$A$445)
A19: Scheduling enabled | B19: =SUMPRODUCT(--(Locations!$M$2:$M$445=TRUE))
A20: Ever took a booking | B20: =SUMPRODUCT(--(Locations!$O$2:$O$445>0))
A21: Took a booking in last 30 days | B21: =SUMPRODUCT(--(Locations!$T$2:$T$445>=$B$3-30)) | C21: Relative to as-of date
A22: Dormant share of enabled | B22: =1-B18/B16 | C22: Enabled but not booking in last 30 days
A23: Payments configured | B23: =SUMPRODUCT(--(Locations!$J$2:$J$445=TRUE))
A24: Payments explicitly skipped | B24: =SUMPRODUCT(--(Locations!$K$2:$K$445=TRUE)) | C24: The single biggest drop-off in the funnel
A25: Value processed (USD) | B25: =SUM(Locations!$V$2:$V$445) | C25: Covers the 444 onboarding locations only. All-entity total is $645,568 across 139 accounts — one paying entity sits outside the onboarding table (delta $13,532).
A26: Accounts that processed a payment | B26: =SUMPRODUCT(--(Locations!$U$2:$U$445>0)) | C26: 138 here vs 139 all-entity, same reason as above.
A27: Locations linked to a billed account | B27: =SUMPRODUCT(--(Locations!$W$2:$W$445<>"")) | C27: 444 are LOCATIONS, not accounts

Sheet July Pitch Funnel
A1: SUPERSEDED - JULY PITCH FIGURES ON THIS SHEET ARE WRONG. DO NOT QUOTE.
A2: Audit 03/08/26: the offer regex had no word boundary, so 'our booking platform' also matched 'y-our booking platform'. Reps saying "YOUR booking platform" (the customer's existing system) were counted as Zoca pitches - 55% false positives on a 22-call sample. Counting was also per Chargebee customer record, and 89 emails map to multiple records. CORRECTED: 63 accounts pitched (not 98); 8 reached scheduling enabled (not 15); 12.7% conversion (not 15%).
A3: UNAFFECTED: adoption funnel (444 locations, 368 enabled, 147 booking in 30d), payments ($645,568 / 139 accounts), cohort retention and migration sources use no regex and stand as published.
A4: July 2026 — from every recorded call down to 98 pitched accounts
A5: Stages 1-5 are call-level counts fixed by the source query. Stages 6-9 calculate live from the Pitched Accounts sheet.
A7: # | B7: Stage | C7: Count | D7: Unit | E7: Note
A8: 1 | B8: Calls recorded in July 2026 | C8: 1051 | D8: calls | E8: sales.fireflies_meeting
A9: 2 | B9: …with a transcript | C9: 1046 | D9: calls | E9: 5 rows have no transcript
A10: 3 | B10: …with an external (non-Zoca) participant | C10: 777 | D10: calls | E10: 433 distinct external emails
A11: 4 | B11: …mapped to a known Chargebee account | C11: 462 | D11: calls | E11: 230 distinct accounts
A12: 5 | B12: Accounts whose call discussed booking/scheduling | C12: 141 | D12: accounts | E12: product mentioned at all
A13: 6 | B13: Accounts that heard an explicit offer | C13: =SUMPRODUCT(--('Pitched Accounts'!$H$2:$H$111>0)) | D13: accounts | E13: offer regex matched
A14: 7 | B14: …minus those already live on Zoca scheduling | C14: =-SUMPRODUCT(--('Pitched Accounts'!$J$2:$J$111=TRUE)) | D14: accounts | E14: support, not a pitch
A15: 8 | B15: ACCOUNTS PITCHED | C15: =SUMPRODUCT(--('Pitched Accounts'!$J$2:$J$111=FALSE)) | D15: accounts | E15: the answer
B17: Outcome for the 98 pitched | C17: Accounts | D17: Rate
B18: Pitched | C18: =SUMPRODUCT(--('Pitched Accounts'!$J$2:$J$111=FALSE)) | D18: =C15/$C$15
B19: Started onboarding after the call | C19: =SUMPRODUCT(--('Pitched Accounts'!$J$2:$J$111=FALSE),--('Pitched Accounts'!$K$2:$K$111<>"")) | D19: =C16/$C$15
B20: Reached scheduling enabled | C20: =SUMPRODUCT(--('Pitched Accounts'!$J$2:$J$111=FALSE),--('Pitched Accounts'!$N$2:$N$111=TRUE)) | D20: =C17/$C$15
B21: Never started onboarding | C21: =SUMPRODUCT(--('Pitched Accounts'!$J$2:$J$111=FALSE),--('Pitched Accounts'!$K$2:$K$111="")) | D21: =C18/$C$15
A23: Coverage: only accounts whose attendee email matched a Chargebee customer are counted (230 of 433 distinct external emails, 53%). A further ~84 pitched emails match no customer record — prospects, excluded deliberately. 98 is a floor.

Sheet Pitched Accounts
A1: SUPERSEDED - JULY PITCH FIGURES ON THIS SHEET ARE WRONG. DO NOT QUOTE.
A2: Audit 03/08/26: the offer regex had no word boundary, so 'our booking platform' also matched 'y-our booking platform'. Reps saying "YOUR booking platform" (the customer's existing system) were counted as Zoca pitches - 55% false positives on a 22-call sample. Counting was also per Chargebee customer record, and 89 emails map to multiple records. CORRECTED: 63 accounts pitched (not 98); 8 reached scheduling enabled (not 15); 12.7% conversion (not 15%).
A3: UNAFFECTED: adoption funnel (444 locations, 368 enabled, 147 booking in 30d), payments ($645,568 / 139 accounts), cohort retention and migration sources use no regex and stand as published.
A4: Account | B4: Contact email | C4: MRR (USD) | D4: Sub status | E4: First call | F4: Last call | G4: Scheduling calls | H4: Offer calls | I4: First offer call — click to open in Fireflies | J4: Already live at pitch (excluded) | K4: Onboarding started | L4: Opted in | M4: Onboarding completed | N4: Scheduling enabled | O4: Payments configured | P4: Native bookings | Q4: Online bookings | R4: Last booking | S4: Mindbody | T4: Vagaro | U4: Booksy | V4: Fresha | W4: GlossGenius | X4: Acuity | Y4: Other tool | Z4: Deposits discussed | AA4: First offer call date | AB4: Call length (min) | AC4: Last offer call date | AD4: Fireflies URL — first offer | AE4: Fireflies URL — last offer
A5: J Madison Spa | B5: info@jmadisonspa.com | C5: 199 | D5: active | E5: 46204 | F5: 46212 | G5: 2 | H5: 2 | I5: J Madison Spa X Zoca | Check In July | J5: FALSE | L5: FALSE | M5: FALSE | N5: FALSE | O5: FALSE | P5: 0 | Q5: 0 | S5: FALSE | T5: FALSE | U5: FALSE | V5: FALSE | W5: FALSE | X5: FALSE | Y5: TRUE | Z5: TRUE | AA5: 46204 | AC5: 46212 | AD5: https://app.fireflies.ai/view/01KWCTTN3RNN15K1BER97NS33X | AE5: https://app.fireflies.ai/view/01KWYP7KBP026M401V03SN6F8Z
A6: Glenn | B6: Glennemeryskincare@gmail.com | C6: 149 | D6: active | E6: 46204 | F6: 46224 | G6: 4 | H6: 2 | I6: Glenn Emery Skincare X Zoca | Check In July | J6: FALSE | K6: 46205 | L6: TRUE | M6: TRUE | N6: TRUE | O6: TRUE | P6: 3 | Q6: 1 | R6: 46232 | S6: FALSE | T6: FALSE | U6: TRUE | V6: FALSE | W6: TRUE | X6: TRUE | Y6: FALSE | Z6: TRUE | AA6: 46204 | AC6: 46224 | AD6: https://app.fireflies.ai/view/01KWETFRAE7VJAPRPBD4TPFH83 | AE6: https://app.fireflies.ai/view/01KY083YEVGV3SQKWRXT54C710
A7: Be Tamed Hair Salon | B7: dreamphotographydfw@gmail.com | E7: 46204 | F7: 46209 | G7: 4 | H7: 2 | I7: Be Tamed Hair Salon X Zoca | Check In July | J7: FALSE | L7: FALSE | M7: FALSE | N7: FALSE | O7: FALSE | P7: 0 | Q7: 0 | S7: FALSE | T7: FALSE | U7: FALSE | V7: FALSE | W7: FALSE | X7: FALSE | Y7: FALSE | Z7: TRUE | AA7: 46204 | AC7: 46206 | AD7: https://app.fireflies.ai/view/01KWAJMPQTHXK62CHES8MP5MFS | AE7: https://app.fireflies.ai/view/01KWMM8M3J8PPNJJ2BNQEAEABH
A8: Rosado Beauty | B8: danielarosadoart@gmail.com | C8: 300 | D8: active | E8: 46204 | F8: 46211 | G8: 3 | H8: 3 | I8: Rosado Beauty X Zoca | Check In July | J8: FALSE | L8: FALSE | M8: FALSE | N8: FALSE | O8: FALSE | P8: 0 | Q8: 0 | S8: FALSE | T8: FALSE | U8: FALSE | V8: FALSE | W8: TRUE | X8: FALSE | Y8: FALSE | Z8: TRUE | AA8: 46204 | AB8: 45 | AC8: 46211 | AD8: https://app.fireflies.ai/view/01KWAK2D8NJRQNAVVCQV5PT97F | AE8: https://app.fireflies.ai/view/01KX0TKCEA6W59HEG10SWTDBFP
A9: Forever Balanced Massage | B9: darrinlane0@gmail.com | C9: 99 | D9: active | E9: 46205 | F9: 46219 | G9: 3 | H9: 2 | I9: Forever Balanced Massage X Zoca | Check In July | J9: FALSE | K9: 46210 | L9: TRUE | M9: TRUE | N9: TRUE | O9: FALSE | P9: 13 | Q9: 7 | R9: 46237 | S9: FALSE | T9: FALSE | U9: FALSE | V9: FALSE | W9: FALSE | X9: FALSE | Y9: FALSE | Z9: TRUE | AA9: 46205 | AC9: 46210 | AD9: https://app.fireflies.ai/view/01KWD6Z9869YYFXXGBXEJPVFTJ | AE9: https://app.fireflies.ai/view/01KWJJKZN53B8MSWT4DVRZ57R2
A10: Seven Layer Skin | B10: sevenlayerskin.ri@gmail.com | C10: 76.04 | D10: active | E10: 46205 | F10: 46205 | G10: 1 | H10: 1 | I10: Seven Layer Skin X Zoca | Check In July | J10: FALSE | L10: FALSE | M10: FALSE | N10: FALSE | O10: FALSE | P10: 0 | Q10: 0 | S10: FALSE | T10: FALSE | U10: FALSE | V10: FALSE | W10: FALSE | X10: FALSE | Y10: FALSE | Z10: TRUE | AA10: 46205 | AC10: 46205 | AD10: https://app.fireflies.ai/view/01KWFSZ5SJH6JF865SN7FNQ472 | AE10: https://app.fireflies.ai/view/01KWFSZ5SJH6JF865SN7FNQ472
A11: L&R Beauty | B11: lianacumbie585@gmail.com | C11: 199 | D11: active | E11: 46205 | F11: 46217 | G11: 3 | H11: 1 | I11: L&R Beauty X Zoca | Check In July | J11: TRUE | K11: 46181 | L11: TRUE | M11: TRUE | N11: TRUE | O11: TRUE | P11: 11 | Q11: 4 | R11: 46226 | S11: FALSE | T11: FALSE | U11: FALSE | V11: FALSE | W11: FALSE | X11: FALSE | Y11: FALSE | Z11: TRUE | AA11: 46205 | AC11: 46205 | AD11: https://app.fireflies.ai/view/01KWFEQ7KEX8RW3D76HKM9RHY2 | AE11: https://app.fireflies.ai/view/01KWFEQ7KEX8RW3D76HKM9RHY2
A12: SolVita Wellness Spa | B12: spadirector@mysolvita.com | C12: 249 | D12: active | E12: 46205 | F12: 46224 | G12: 3 | H12: 3 | I12: SolVita Wellness Spa X Zoca | Check In July | J12: FALSE | L12: FALSE | M12: FALSE | N12: FALSE | O12: FALSE | P12: 0 | Q12: 0 | S12: FALSE | T12: FALSE | U12: FALSE | V12: FALSE | W12: FALSE | X12: FALSE | Y12: FALSE | Z12: FALSE | AA12: 46205 | AC12: 46224 | AD12: https://app.fireflies.ai/view/01KWFY893YVKTQZP6890KFVA1M | AE12: https://app.fireflies.ai/view/01KY1AD4E1834PDFT2EJE4D0QA
A13: The Sculpt Spa | B13: thesculptspa@gmail.com | C13: 150 | D13: active | E13: 46205 | F13: 46223 | G13: 2 | H13: 2 | I13: The Sculpt Spa | J13: TRUE | K13: 46083 | L13: TRUE | M13: TRUE | N13: TRUE | O13: TRUE | P13: 6 | Q13: 6 | R13: 46199 | S13: FALSE | T13: FALSE | U13: FALSE | V13: FALSE | W13: FALSE | X13: FALSE | Y13: TRUE | Z13: TRUE | AA13: 46205 | AB13: 48 | AC13: 46223 | AD13: https://app.fireflies.ai/view/01KWJ6XA7E2C0TPBT5HX5PDWXZ | AE13: https://app.fireflies.ai/view/01KY07FQYHZT1CEYT2J524VKT0
A14: LeenaZoca | B14: desouza.leena@gmail.com | C14: 200 | D14: active | E14: 46206 | F14: 46209 | G14: 2 | H14: 1 | I14: LeenaZoca | J14: TRUE | K14: 46113 | L14: TRUE | M14: TRUE | N14: TRUE | O14: FALSE | P14: 531 | Q14: 80 | R14: 46236 | S14: FALSE | T14: FALSE | U14: FALSE | V14: FALSE | W14: FALSE | X14: FALSE | Y14: FALSE | Z14: FALSE | AA14: 46206 | AC14: 46206 | AD14: https://app.fireflies.ai/view/01KWGBVKBD29P2Q5B1D56XQXA8 | AE14: https://app.fireflies.ai/view/01KWGBVKBD29P2Q5B1D56XQXA8
A15: Saged NYC Beauty & Wellness | B15: sagednyc@gmail.com | C15: 159 | D15: active | E15: 46206 | F15: 46226 | G15: 2 | H15: 2 | I15: Saged NYC Beauty & Wellness X Zoca | Check In July | J15: FALSE | L15: FALSE | M15: FALSE | N15: FALSE | O15: FALSE | P15: 0 | Q15: 0 | S15: FALSE | T15: FALSE | U15: FALSE | V15: FALSE | W15: FALSE | X15: FALSE | Y15: FALSE | Z15: TRUE | AA15: 46206 | AB15: 59 | AC15: 46226 | AD15: https://app.fireflies.ai/view/01KWMMM9YF2D3M244HJ4442SBS | AE15: https://app.fireflies.ai/view/01KY7PZTWWHAE021KQ5D8NT853
A16: ZOCA | B16: fabulouscitysalon@gmail.com | C16: 200 | D16: active | E16: 46207 | F16: 46216 | G16: 2 | H16: 2 | I16: ZOCA <> Fabulouscity Beauty Salon | J16: FALSE | L16: FALSE | M16: FALSE | N16: FALSE | O16: FALSE | P16: 0 | Q16: 0 | S16: FALSE | T16: FALSE | U16: FALSE | V16: TRUE | W16: FALSE | X16: FALSE | Y16: FALSE | Z16: TRUE | AA16: 46207 | AB16: 11 | AC16: 46216 | AD16: https://app.fireflies.ai/view/01KWMR7GGCP9H5BK5XA8171XVT | AE16: https://app.fireflies.ai/view/01KXEE3YCVKPKCAC3NZXNDVNR8
A17: Wellness Your Way | B17: info@wellness-yourway.com | C17: 249 | D17: active | E17: 46209 | F17: 46223 | G17: 2 | H17: 1 | I17: Wellness Your Way X Zoca | Check In July | J17: FALSE | L17: FALSE | M17: FALSE | N17: FALSE | O17: FALSE | P17: 0 | Q17: 0 | S17: TRUE | T17: TRUE | U17: FALSE | V17: TRUE | W17: TRUE | X17: FALSE | Y17: FALSE | Z17: TRUE | AA17: 46209 | AB17: 73 | AC17: 46209 | AD17: https://app.fireflies.ai/view/01KWVPTCMXKB5J9ZD0K6VW5GG7 | AE17: https://app.fireflies.ai/view/01KWVPTCMXKB5J9ZD0K6VW5GG7
A18: Essence Esthetics: Skin · Lashes · Brows | B18: eesthetics7@gmail.com | C18: 100 | D18: active | E18: 46209 | F18: 46231 | G18: 3 | H18: 1 | I18: Essence Esthetics: Skin · Lashes · Brows X Zoca | Check In July | J18: FALSE | K18: 46210 | L18: TRUE | M18: TRUE | N18: TRUE | O18: TRUE | P18: 22 | Q18: 7 | R18: 46234 | S18: FALSE | T18: FALSE | U18: FALSE | V18: FALSE | W18: FALSE | X18: FALSE | Y18: FALSE | Z18: TRUE | AA18: 46210 | AB18: 138 | AC18: 46210 | AD18: https://app.fireflies.ai/view/01KWW3XDSQFPYC39AHE7X1QYEK | AE18: https://app.fireflies.ai/view/01KWW3XDSQFPYC39AHE7X1QYEK
A19: Donna Skin and Body Care | B19: donna.skin@gmail.com | C19: 150 | D19: active | E19: 46209 | F19: 46224 | G19: 4 | H19: 2 | I19: Donna Skin and Body Care X Zoca | Check In April | J19: TRUE | K19: 46169 | L19: TRUE | M19: TRUE | N19: TRUE | O19: TRUE | P19: 104 | Q19: 6 | R19: 46237 | S19: FALSE | T19: FALSE | U19: FALSE | V19: FALSE | W19: FALSE | X19: FALSE | Y19: FALSE | Z19: TRUE | AA19: 46216 | AB19: 33 | AC19: 46218 | AD19: https://app.fireflies.ai/view/01KWZ35QJGW8H8Y89FW82ARM9C | AE19: https://app.fireflies.ai/view/01KXE8RVTRA5HEWFSJA8RCSJTT
A20: Xanzalyn Beauty & Dermacare | B20: pamperedimagellc@gmail.com | E20: 46209 | F20: 46232 | G20: 2 | H20: 2 | I20: Xanzalyn Beauty & Dermacare X Zoca | Check In July | J20: FALSE | K20: 46232 | L20: TRUE | M20: FALSE | N20: FALSE | O20: FALSE | P20: 0 | Q20: 0 | S20: FALSE | T20: FALSE | U20: FALSE | V20: FALSE | W20: FALSE | X20: FALSE | Y20: FALSE | Z20: FALSE | AA20: 46209 | AB20: 18 | AC20: 46232 | AD20: https://app.fireflies.ai/view/01KWW3B796KPZEWZBRJE2D374M | AE20: https://app.fireflies.ai/view/01KYQ1NKE2JBW3345GG4Q8EACJ
A21: Lasting Beauty Spa | B21: info@lastingbeautyspa.com | C21: 120 | D21: active | E21: 46210 | F21: 46210 | G21: 1 | H21: 1 | I21: Lasting Beauty Spa X Zoca | Check In February | J21: FALSE | L21: FALSE | M21: FALSE | N21: FALSE | O21: FALSE | P21: 0 | Q21: 0 | S21: FALSE | T21: FALSE | U21: FALSE | V21: FALSE | W21: FALSE | X21: FALSE | Y21: FALSE | Z21: FALSE | AA21: 46210 | AB21: 44 | AC21: 46210 | AD21: https://app.fireflies.ai/view/01KWSEMR4B4B1B2JXMJWKSTFVM | AE21: https://app.fireflies.ai/view/01KWSEMR4B4B1B2JXMJWKSTFVM
A22: Nbraidstyles | B22: erudiceazonvide@gmail.com | C22: 135 | D22: active | E22: 46210 | F22: 46210 | G22: 1 | H22: 1 | I22: Nbraidstyles X Zoca | Check In July | J22: TRUE | K22: 46052 | L22: TRUE | M22: TRUE | N22: TRUE | O22: TRUE | P22: 273 | Q22: 73 | R22: 46237 | S22: FALSE | T22: FALSE | U22: FALSE | V22: FALSE | W22: FALSE | X22: FALSE | Y22: FALSE | Z22: FALSE | AA22: 46210 | AB22: 19 | AC22: 46210 | AD22: https://app.fireflies.ai/view/01KWYDAQMWGWG0KAQN11KWANJQ | AE22: https://app.fireflies.ai/view/01KWYDAQMWGWG0KAQN11KWANJQ
A23: Glow Skin Care | B23: umakemeglow@gmail.com | C23: 100 | D23: active | E23: 46210 | F23: 46227 | G23: 3 | H23: 1 | I23: Glow Skin Care X Zoca | Check In July | J23: FALSE | L23: FALSE | M23: FALSE | N23: FALSE | O23: FALSE | P23: 0 | Q23: 0 | S23: FALSE | T23: TRUE | U23: FALSE | V23: FALSE | W23: FALSE | X23: FALSE | Y23: FALSE | Z23: TRUE | AA23: 46210 | AC23: 46210 | AD23: https://app.fireflies.ai/view/01KWSP6FJGJ1SM0G3G1AJCRD26 | AE23: https://app.fireflies.ai/view/01KWSP6FJGJ1SM0G3G1AJCRD26
A24: Truve Fit | B24: alison@truvefit.com | E24: 46210 | F24: 46210 | G24: 1 | H24: 1 | I24: Truve Fit X Zoca | Check In July | J24: FALSE | L24: FALSE | M24: FALSE | N24: FALSE | O24: FALSE | P24: 0 | Q24: 0 | S24: FALSE | T24: FALSE | U24: FALSE | V24: FALSE | W24: FALSE | X24: FALSE | Y24: FALSE | Z24: TRUE | AA24: 46210 | AB24: 43 | AC24: 46210 | AD24: https://app.fireflies.ai/view/01KWX09A38MTKGHMKEQA20FXKT | AE24: https://app.fireflies.ai/view/01KWX09A38MTKGHMKEQA20FXKT
A25: All Love Collection | B25: we@alllovecollections.com | E25: 46210 | F25: 46223 | G25: 4 | H25: 3 | I25: Zoca <> All Love Collections | J25: FALSE | L25: FALSE | M25: FALSE | N25: FALSE | O25: FALSE | P25: 0 | Q25: 0 | S25: FALSE | T25: FALSE | U25: FALSE | V25: FALSE | W25: FALSE | X25: FALSE | Y25: FALSE | Z25: FALSE | AA25: 46210 | AB25: 84 | AC25: 46223 | AD25: https://app.fireflies.ai/view/01KWYZ11PSSAV6FVBDCZHKE3QA | AE25: https://app.fireflies.ai/view/01KXWAE7DJECPTQGX688MFETEP
A26: Just Because Hair Therapy Salon | B26: justbecausesalon@me.com | C26: 249 | D26: active | E26: 46210 | F26: 46210 | G26: 1 | H26: 1 | I26: Just Because Hair Therapy Salon X Zoca | Check In July | J26: FALSE | K26: 46210 | L26: TRUE | M26: TRUE | N26: TRUE | O26: TRUE | P26: 15 | Q26: 6 | R26: 46234 | S26: FALSE | T26: FALSE | U26: FALSE | V26: FALSE | W26: FALSE | X26: FALSE | Y26: FALSE | Z26: TRUE | AA26: 46210 | AB26: 60 | AC26: 46210 | AD26: https://app.fireflies.ai/view/01KWY3H2GSW906CGXTJ5XJCQ9E | AE26: https://app.fireflies.ai/view/01KWY3H2GSW906CGXTJ5XJCQ9E
A27: Lash and Skin Studio | B27: erica.business14@gmail.com | C27: 299 | D27: active | E27: 46210 | F27: 46210 | G27: 1 | H27: 1 | I27: Lash and Skin Studio X Zoca | Check In July | J27: FALSE | L27: FALSE | M27: FALSE | N27: FALSE | O27: FALSE | P27: 0 | Q27: 0 | S27: FALSE | T27: FALSE | U27: TRUE | V27: FALSE | W27: TRUE | X27: FALSE | Y27: FALSE | Z27: TRUE | AA27: 46210 | AB27: 46 | AC27: 46210 | AD27: https://app.fireflies.ai/view/01KWWETADJJ1REW0AQYSWQ3DTZ | AE27: https://app.fireflies.ai/view/01KWWETADJJ1REW0AQYSWQ3DTZ
A28: Anu & Isabella | B28: bellaxxx19@gmail.com | C28: 100 | D28: active | E28: 46211 | F28: 46211 | G28: 1 | H28: 1 | I28: Anu & Isabella | J28: FALSE | L28: FALSE | M28: FALSE | N28: FALSE | O28: FALSE | P28: 0 | Q28: 0 | S28: FALSE | T28: FALSE | U28: FALSE | V28: FALSE | W28: FALSE | X28: FALSE | Y28: FALSE | Z28: FALSE | AA28: 46211 | AB28: 12 | AC28: 46211 | AD28: https://app.fireflies.ai/view/01KWZ6ZG7DNJWDF79P4PJ1DNPF | AE28: https://app.fireflies.ai/view/01KWZ6ZG7DNJWDF79P4PJ1DNPF
A29: Ksweetshaircompany® Medical Wigs & Hair Restoration | B29: Ksweetshaircompany@gmail.com | E29: 46211 | F29: 46232 | G29: 2 | H29: 1 | I29: Ksweetshaircompany® Medical Wigs & Hair Restoration X Zoca | Check In | J29: FALSE | L29: FALSE | M29: FALSE | N29: FALSE | O29: FALSE | P29: 0 | Q29: 0 | S29: FALSE | T29: FALSE | U29: FALSE | V29: FALSE | W29: FALSE | X29: FALSE | Y29: FALSE | Z29: FALSE | AA29: 46211 | AC29: 46211 | AD29: https://app.fireflies.ai/view/01KWYCRBSZK2MKY8K7EFYNQZ8D | AE29: https://app.fireflies.ai/view/01KWYCRBSZK2MKY8K7EFYNQZ8D
A30: mcbh58 | B30: mcbh58@gmail.com | C30: 199 | D30: active | E30: 46211 | F30: 46211 | G30: 1 | H30: 1 | I30: CHECK-IN MEET | J30: FALSE | L30: FALSE | M30: FALSE | N30: FALSE | O30: FALSE | P30: 0 | Q30: 0 | S30: FALSE | T30: FALSE | U30: FALSE | V30: FALSE | W30: TRUE | X30: FALSE | Y30: FALSE | Z30: TRUE | AA30: 46211 | AC30: 46211 | AD30: https://app.fireflies.ai/view/01KWJJKZN0M986T9CR1CM0ZPK8 | AE30: https://app.fireflies.ai/view/01KWJJKZN0M986T9CR1CM0ZPK8
A31: Beverly Beauty Skincare & Spa | B31: beverlybeauty06@gmail.com | C31: 149 | D31: active | E31: 46211 | F31: 46211 | G31: 1 | H31: 1 | I31: Beverly Beauty Skincare & Spa | Facials|Skin Rejuvenation |lashes| wax | J31: FALSE | L31: FALSE | M31: FALSE | N31: FALSE | O31: FALSE | P31: 0 | Q31: 0 | S31: FALSE | T31: FALSE | U31: FALSE | V31: FALSE | W31: TRUE | X31: FALSE | Y31: FALSE | Z31: FALSE | AA31: 46211 | AB31: 32 | AC31: 46211 | AD31: https://app.fireflies.ai/view/01KWZ6G71XX95MZGN242RTERVN | AE31: https://app.fireflies.ai/view/01KWZ6G71XX95MZGN242RTERVN
A32: Anu & Deborah- Satori Massage | B32: debhpc@gmail.com | C32: 250 | D32: active | E32: 46211 | F32: 46230 | G32: 3 | H32: 2 | I32: Anu & Deborah- Satori Massage | J32: FALSE | L32: FALSE | M32: FALSE | N32: FALSE | O32: FALSE | P32: 0 | Q32: 0 | S32: FALSE | T32: TRUE | U32: FALSE | V32: FALSE | W32: FALSE | X32: FALSE | Y32: FALSE | Z32: FALSE | AA32: 46216 | AB32: 183 | AC32: 46230 | AD32: https://app.fireflies.ai/view/01KX9HGY3F1FE7NV3FB7Q8GK4W | AE32: https://app.fireflies.ai/view/01KYJ1ZCG58VKPE4ZNJVJ2ZW9K
A33: Perfectly Bare Wax | B33: perfectlybarewaxbar@gmail.com | C33: 746 | D33: active | E33: 46211 | F33: 46211 | G33: 1 | H33: 1 | I33: Perfectly Bare Wax X Zoca | Social Media Onboarding | J33: FALSE | L33: FALSE | M33: FALSE | N33: FALSE | O33: FALSE | P33: 0 | Q33: 0 | S33: FALSE | T33: FALSE | U33: FALSE | V33: FALSE | W33: FALSE | X33: FALSE | Y33: FALSE | Z33: FALSE | AA33: 46211 | AC33: 46211 | AD33: https://app.fireflies.ai/view/01KWZEF6KNDECHX8JBN2330AQQ | AE33: https://app.fireflies.ai/view/01KWZEF6KNDECHX8JBN2330AQQ
A34: Skinclub Wellness Center & Med Spa | B34: afsoonsmith97@gmail.com | E34: 46211 | F34: 46220 | G34: 3 | H34: 1 | I34: Skinclub Wellness Center & Med Spa X Zoca | Check In July | J34: FALSE | L34: FALSE | M34: FALSE | N34: FALSE | O34: FALSE | P34: 0 | Q34: 0 | S34: FALSE | T34: FALSE | U34: FALSE | V34: FALSE | W34: FALSE | X34: FALSE | Y34: FALSE | Z34: FALSE | AA34: 46220 | AB34: 42 | AC34: 46220 | AD34: https://app.fireflies.ai/view/01KXP62QZ2DFHTGSVBVD5HGBVN | AE34: https://app.fireflies.ai/view/01KXP62QZ2DFHTGSVBVD5HGBVN
A35: Michael's Salon | B35: baturov11@gmail.com | C35: 130 | D35: active | E35: 46211 | F35: 46211 | G35: 1 | H35: 1 | I35: Michael's Salon X Zoca | Check In July | J35: FALSE | K35: 46223 | L35: TRUE | M35: TRUE | N35: TRUE | O35: FALSE | P35: 1 | Q35: 1 | R35: 46235 | S35: FALSE | T35: FALSE | U35: FALSE | V35: FALSE | W35: TRUE | X35: FALSE | Y35: FALSE | Z35: FALSE | AA35: 46211 | AB35: 34 | AC35: 46211 | AD35: https://app.fireflies.ai/view/01KWZ3XX5D6RBMQN94T3P4N832 | AE35: https://app.fireflies.ai/view/01KWZ3XX5D6RBMQN94T3P4N832
A36: Anu & Christopher | B36: Christhecolorist2020@gmail.com | C36: 249 | D36: active | E36: 46211 | F36: 46211 | G36: 2 | H36: 1 | I36: Anu & Christopher | J36: FALSE | L36: FALSE | M36: FALSE | N36: FALSE | O36: FALSE | P36: 0 | Q36: 0 | S36: FALSE | T36: FALSE | U36: FALSE | V36: TRUE | W36: FALSE | X36: FALSE | Y36: FALSE | Z36: TRUE | AA36: 46211 | AB36: 40 | AC36: 46211 | AD36: https://app.fireflies.ai/view/01KX1QWKXAS1D9QE9CC0YHWJMG | AE36: https://app.fireflies.ai/view/01KX1QWKXAS1D9QE9CC0YHWJMG
A37: Simply Facials | B37: Mysimplyfacials@gmail.com | C37: 199 | D37: active | E37: 46211 | F37: 46211 | G37: 1 | H37: 1 | I37: Simply Facials | Thousand Oaks Esthetician X Zoca | Check In July | J37: TRUE | K37: 46104 | L37: TRUE | M37: TRUE | N37: TRUE | O37: TRUE | P37: 893 | Q37: 3 | R37: 46140 | S37: FALSE | T37: FALSE | U37: FALSE | V37: FALSE | W37: TRUE | X37: FALSE | Y37: FALSE | Z37: FALSE | AA37: 46211 | AB37: 32 | AC37: 46211 | AD37: https://app.fireflies.ai/view/01KWYGY66G975WRPTF35JM4F0J | AE37: https://app.fireflies.ai/view/01KWYGY66G975WRPTF35JM4F0J
A38: ZOCA | B38: bookings@danielkpalmer.com | C38: 249.67 | D38: active | E38: 46211 | F38: 46225 | G38: 2 | H38: 2 | I38: ZOCA <> Daniel K Palmer Salon | J38: FALSE | L38: FALSE | M38: FALSE | N38: FALSE | O38: FALSE | P38: 0 | Q38: 0 | S38: FALSE | T38: FALSE | U38: FALSE | V38: FALSE | W38: FALSE | X38: FALSE | Y38: FALSE | Z38: TRUE | AA38: 46211 | AB38: 27 | AC38: 46225 | AD38: https://app.fireflies.ai/view/01KX1P0KMHT8PXYDYJN8B91EK6 | AE38: https://app.fireflies.ai/view/01KY0QQAWMZJXP0BD721A2ZKD4
A39: Dr Shermi-Laser Skin & Wellness Center | B39: drparikh00@gmail.com | C39: 250 | D39: active | E39: 46212 | F39: 46226 | G39: 2 | H39: 1 | I39: Zoca - Dr Shermi-Laser Skin & Wellness Center | J39: FALSE | K39: 46212 | L39: TRUE | M39: FALSE | N39: FALSE | O39: FALSE | P39: 0 | Q39: 0 | S39: FALSE | T39: FALSE | U39: FALSE | V39: FALSE | W39: FALSE | X39: FALSE | Y39: FALSE | Z39: FALSE | AA39: 46226 | AB39: 181 | AC39: 46226 | AD39: https://app.fireflies.ai/view/01KY2X84QR7631VMNWQE4JJ677 | AE39: https://app.fireflies.ai/view/01KY2X84QR7631VMNWQE4JJ677
A40: NatalieZoca | B40: natalietlindo@gmail.com | C40: 329 | D40: active | E40: 46212 | F40: 46213 | G40: 2 | H40: 2 | I40: NatalieZoca | J40: FALSE | L40: FALSE | M40: FALSE | N40: FALSE | O40: FALSE | P40: 0 | Q40: 0 | S40: FALSE | T40: FALSE | U40: FALSE | V40: FALSE | W40: FALSE | X40: FALSE | Y40: FALSE | Z40: TRUE | AA40: 46212 | AC40: 46213 | AD40: https://app.fireflies.ai/view/01KX1MYVNPSDVG0504QQGNA4FF | AE40: https://app.fireflies.ai/view/01KX410ZK2Y17S3ARK3DNJS6F5
...

Sheet Adoption Funnel
A1: Scheduling adoption funnel — all 444 onboarding locations, 30/01/26 to 31/07/26
A2: Every count calculates from the Locations sheet.
A4: Stage | B4: Locations | C4: % of entered | D4: Reading
A5: Entered onboarding | B5: =COUNTA(Locations!$A$2:$A$445) | C5: =B5/$B$5 | D5: Denominator
A6: Opted in | B6: =SUMPRODUCT(--(Locations!$E$2:$E$445=TRUE)) | C6: =B6/$B$5
A7: Business details set | B7: =SUMPRODUCT(--(Locations!$F$2:$F$445=TRUE)) | C7: =B7/$B$5
A8: Services configured | B8: =SUMPRODUCT(--(Locations!$G$2:$G$445=TRUE)) | C8: =B8/$B$5
A9: Booking rules configured | B9: =SUMPRODUCT(--(Locations!$H$2:$H$445=TRUE)) | C9: =B9/$B$5
A10: Booking policies configured | B10: =SUMPRODUCT(--(Locations!$I$2:$I$445=TRUE)) | C10: =B10/$B$5
A11: Website flipped to Zoca booking | B11: =SUMPRODUCT(--(Locations!$N$2:$N$445=TRUE)) | C11: =B11/$B$5
A12: Onboarding completed | B12: =SUMPRODUCT(--(Locations!$L$2:$L$445=TRUE)) | C12: =B12/$B$5
A13: Scheduling enabled | B13: =SUMPRODUCT(--(Locations!$M$2:$M$445=TRUE)) | C13: =B13/$B$5 | D13: SETUP conversion
A14: Payments configured | B14: =SUMPRODUCT(--(Locations!$J$2:$J$445=TRUE)) | C14: =B14/$B$5 | D14: The wall
A15: Payments explicitly skipped | B15: =SUMPRODUCT(--(Locations!$K$2:$K$445=TRUE)) | C15: =B15/$B$5 | D15: The wall
A16: Ever took a booking | B16: =SUMPRODUCT(--(Locations!$O$2:$O$445>0)) | C16: =B16/$B$5 | D16: ACTIVATION conversion
A17: Ever took a customer-made online booking | B17: =SUMPRODUCT(--(Locations!$P$2:$P$445>0)) | C17: =B17/$B$5
A18: Booked in last 90 days | B18: =SUMPRODUCT(--(Locations!$T$2:$T$445>=Summary!$B$3-90)) | C18: =B18/$B$5 | D18: 198 here vs 196 in the report: the report used query-run time, this uses the fixed as-of date (a ~16h wider window). This is the reproducible one.
A19: Booked in last 30 days | B19: =SUMPRODUCT(--(Locations!$T$2:$T$445>=Summary!$B$3-30)) | C19: =B19/$B$5 | D19: SUSTAINED conversion
A21: Three different conversion rates live in this one funnel. Say which one you are quoting: setup 83%, activation 64%, sustained 33%.

Sheet Locations
A1: Location entity id | B1: Business name | C1: Onboarding started | D1: Cohort | E1: Opted in | F1: Business details | G1: Services configured | H1: Booking rules | I1: Booking policies | J1: Payments configured | K1: Payments skipped | L1: Onboarding completed | M1: Scheduling enabled | N1: Website flipped | O1: Native bookings | P1: Online bookings | Q1: Migrated bookings | R1: Migration source | S1: First booking | T1: Last booking | U1: Paid transactions | V1: Paid amount (USD) | W1: Chargebee customer id | X1: MRR (USD) | Y1: Subscription status | Z1: Name source
A2: f2930e96-c10f-4273-834d-948790dcb785 | B2: Nbraidstyles | C2: 46052 | D2: 2026-01 | E2: TRUE | F2: TRUE | G2: TRUE | H2: TRUE | I2: TRUE | J2: TRUE | K2: FALSE | L2: TRUE | M2: TRUE | N2: TRUE | O2: 273 | P2: 73 | Q2: 0 | S2: 45202 | T2: 46237 | U2: 69 | V2: 2627 | W2: cus_OGiPoqL0Cu6SL2 | X2: 135 | Y2: active | Z2: gbp
A3: 4dd18bab-a516-46e7-a193-1eb215074802 | B3: timelyAI | C3: 46052 | D3: 2026-01 | E3: TRUE | F3: TRUE | G3: TRUE | H3: TRUE | I3: TRUE | J3: TRUE | K3: FALSE | L3: TRUE | M3: TRUE | N3: TRUE | O3: 5 | P3: 0 | Q3: 0 | S3: 46052 | T3: 46052 | U3: 1 | V3: 1.5 | Z3: gbp
A4: 0a3e4ac6-9bdb-4e76-b354-7e2f2d6bb72c | B4: Natasha super salon | C4: 46053 | D4: 2026-01 | E4: TRUE | F4: TRUE | G4: FALSE | H4: FALSE | I4: FALSE | J4: FALSE | K4: FALSE | L4: FALSE | M4: FALSE | N4: FALSE | O4: 0 | P4: 0 | Q4: 0 | U4: 0 | V4: 0 | Z4: gbp_logs
A5: b31bc9ca-9a1c-4cb7-b76f-7621a2cc9a5c | B5: (name not on file) | C5: 46053 | D5: 2026-01 | E5: TRUE | F5: TRUE | G5: FALSE | H5: FALSE | I5: FALSE | J5: FALSE | K5: FALSE | L5: FALSE | M5: FALSE | N5: FALSE | O5: 0 | P5: 0 | Q5: 0 | U5: 0 | V5: 0 | Z5: unknown
A6: d1983fab-fb1b-43c6-af50-2e25684bdc16 | B6: Natasha super salon | C6: 46053 | D6: 2026-01 | E6: TRUE | F6: TRUE | G6: TRUE | H6: TRUE | I6: TRUE | J6: FALSE | K6: TRUE | L6: TRUE | M6: TRUE | N6: TRUE | O6: 5 | P6: 0 | Q6: 0 | S6: 46053 | T6: 46053 | U6: 0 | V6: 0 | Z6: gbp_logs
A7: c38002b7-6d03-4e9d-9772-c8b9ef9593be | B7: (name not on file) | C7: 46053 | D7: 2026-01 | E7: TRUE | F7: TRUE | G7: TRUE | H7: TRUE | I7: TRUE | J7: FALSE | K7: FALSE | L7: FALSE | M7: FALSE | N7: FALSE | O7: 0 | P7: 0 | Q7: 0 | U7: 0 | V7: 0 | Z7: unknown
A8: 61bcfc8a-d56d-4b46-a4a3-658ce60aa48f | B8: Natasha super salon | C8: 46053 | D8: 2026-01 | E8: TRUE | F8: TRUE | G8: TRUE | H8: TRUE | I8: TRUE | J8: FALSE | K8: TRUE | L8: TRUE | M8: TRUE | N8: TRUE | O8: 3 | P8: 0 | Q8: 0 | S8: 46053 | T8: 46055 | U8: 0 | V8: 0 | Z8: gbp_logs
A9: 06055989-747f-477b-9e4f-36849d39a605 | B9: (name not on file) | C9: 46053 | D9: 2026-01 | E9: TRUE | F9: TRUE | G9: TRUE | H9: TRUE | I9: TRUE | J9: FALSE | K9: TRUE | L9: TRUE | M9: FALSE | N9: FALSE | O9: 0 | P9: 0 | Q9: 0 | U9: 0 | V9: 0 | Z9: unknown
A10: 29021b0b-4156-4d36-b27e-3ae09ac17ce9 | B10: Doom Salon | C10: 46053 | D10: 2026-01 | E10: TRUE | F10: TRUE | G10: TRUE | H10: TRUE | I10: TRUE | J10: FALSE | K10: TRUE | L10: TRUE | M10: TRUE | N10: TRUE | O10: 5 | P10: 3 | Q10: 0 | S10: 46053 | T10: 46055 | U10: 0 | V10: 0 | Z10: gbp_logs
A11: 4c62f8a6-fffd-45fa-9c24-410228f4c0eb | B11: Beauty and a Beast Salon | C11: 46053 | D11: 2026-01 | E11: TRUE | F11: TRUE | G11: TRUE | H11: TRUE | I11: TRUE | J11: TRUE | K11: TRUE | L11: TRUE | M11: TRUE | N11: TRUE | O11: 13 | P11: 3 | Q11: 0 | S11: 46053 | T11: 46055 | U11: 2 | V11: 4881.25 | Z11: gbp_logs
A12: 90d177ff-eef3-48f8-b56c-3bdaf1d1b431 | B12: Saxena's spa | C12: 46055 | D12: 2026-02 | E12: TRUE | F12: TRUE | G12: FALSE | H12: FALSE | I12: FALSE | J12: FALSE | K12: FALSE | L12: FALSE | M12: FALSE | N12: FALSE | O12: 0 | P12: 0 | Q12: 0 | U12: 0 | V12: 0 | Z12: gbp_logs
A13: 07233b3c-c922-40a7-8ac3-e57986ffb675 | B13: Natasha super salon | C13: 46055 | D13: 2026-02 | E13: TRUE | F13: TRUE | G13: TRUE | H13: TRUE | I13: TRUE | J13: FALSE | K13: TRUE | L13: TRUE | M13: TRUE | N13: TRUE | O13: 17 | P13: 9 | Q13: 0 | S13: 46055 | T13: 46056 | U13: 0 | V13: 0 | Z13: gbp_logs
A14: ca0b1b82-9b25-4c51-9ab5-65575cee49c4 | B14: (name not on file) | C14: 46055 | D14: 2026-02 | E14: TRUE | F14: TRUE | G14: TRUE | H14: TRUE | I14: TRUE | J14: FALSE | K14: TRUE | L14: TRUE | M14: TRUE | N14: TRUE | O14: 0 | P14: 0 | Q14: 0 | U14: 0 | V14: 0 | Z14: unknown
A15: 0f95c289-b0a7-4149-97be-2f0e3782cf2c | B15: Shine Salon & Spa | C15: 46055 | D15: 2026-02 | E15: TRUE | F15: TRUE | G15: TRUE | H15: TRUE | I15: TRUE | J15: FALSE | K15: TRUE | L15: TRUE | M15: TRUE | N15: TRUE | O15: 54 | P15: 17 | Q15: 0 | S15: 46055 | T15: 46058 | U15: 39 | V15: 58 | Z15: gbp_logs
A16: e85a1d81-1a0f-41e6-b286-c358d63f8251 | B16: (name not on file) | C16: 46055 | D16: 2026-02 | E16: TRUE | F16: FALSE | G16: FALSE | H16: FALSE | I16: FALSE | J16: FALSE | K16: FALSE | L16: FALSE | M16: FALSE | N16: FALSE | O16: 0 | P16: 0 | Q16: 0 | U16: 0 | V16: 0 | Z16: unknown
A17: 140217cf-0058-4d4c-8814-0235ee218898 | B17: Shine Salon & Spa - Hair, Skin, Nails, Massage | C17: 46055 | D17: 2026-02 | E17: TRUE | F17: TRUE | G17: TRUE | H17: TRUE | I17: TRUE | J17: FALSE | K17: FALSE | L17: FALSE | M17: FALSE | N17: FALSE | O17: 0 | P17: 0 | Q17: 0 | U17: 0 | V17: 0 | Z17: gbp
A18: 736264eb-3de6-49d0-a1fb-6706edc2ac61 | B18: Creations Art and Beauty | C18: 46055 | D18: 2026-02 | E18: TRUE | F18: TRUE | G18: TRUE | H18: TRUE | I18: TRUE | J18: TRUE | K18: FALSE | L18: TRUE | M18: TRUE | N18: TRUE | O18: 23 | P18: 12 | Q18: 0 | S18: 46055 | T18: 46233 | U18: 1 | V18: 1.4 | W18: AzqhpEUzYFk7hC0ut | X18: 350 | Y18: active | Z18: gbp
A19: 27022460-a4b6-4090-b990-c97c73a8f56a | B19: Alia Bhat Makeup | C19: 46056 | D19: 2026-02 | E19: TRUE | F19: TRUE | G19: TRUE | H19: TRUE | I19: TRUE | J19: FALSE | K19: TRUE | L19: TRUE | M19: TRUE | N19: TRUE | O19: 19 | P19: 9 | Q19: 0 | S19: 46056 | T19: 46057 | U19: 0 | V19: 0 | Z19: gbp_logs
A20: 410b7b26-6680-425d-8f37-642290a08d52 | B20: Natasha super salon | C20: 46056 | D20: 2026-02 | E20: TRUE | F20: TRUE | G20: TRUE | H20: TRUE | I20: TRUE | J20: FALSE | K20: TRUE | L20: TRUE | M20: TRUE | N20: TRUE | O20: 14 | P20: 8 | Q20: 0 | S20: 46056 | T20: 46057 | U20: 0 | V20: 0 | Z20: gbp_logs
A21: 5b860bec-4d4b-44d0-b44c-1d70e53990f5 | B21: (name not on file) | C21: 46056 | D21: 2026-02 | E21: TRUE | F21: TRUE | G21: TRUE | H21: TRUE | I21: TRUE | J21: FALSE | K21: TRUE | L21: TRUE | M21: TRUE | N21: TRUE | O21: 0 | P21: 0 | Q21: 0 | U21: 0 | V21: 0 | Z21: unknown
A22: 9cde7f89-b4bd-4bf0-a467-27a8be0e059a | B22: Sylph Salon | C22: 46056 | D22: 2026-02 | E22: TRUE | F22: TRUE | G22: TRUE | H22: TRUE | I22: TRUE | J22: FALSE | K22: TRUE | L22: TRUE | M22: TRUE | N22: TRUE | O22: 3 | P22: 2 | Q22: 0 | S22: 46056 | T22: 46056 | U22: 0 | V22: 0 | Z22: gbp_logs
A23: 0ca958cd-28a7-4da9-b78f-b36897268677 | B23: Superb Salon & Spa | C23: 46056 | D23: 2026-02 | E23: TRUE | F23: TRUE | G23: TRUE | H23: TRUE | I23: TRUE | J23: FALSE | K23: TRUE | L23: TRUE | M23: TRUE | N23: TRUE | O23: 12 | P23: 10 | Q23: 0 | S23: 46056 | T23: 46057 | U23: 0 | V23: 0 | Z23: gbp_logs
A24: 37aef7c8-89d0-477a-8929-604d5927322c | B24: Glamour Salon & Spa | C24: 46056 | D24: 2026-02 | E24: TRUE | F24: TRUE | G24: TRUE | H24: TRUE | I24: TRUE | J24: FALSE | K24: TRUE | L24: TRUE | M24: TRUE | N24: TRUE | O24: 7 | P24: 4 | Q24: 0 | S24: 46069 | T24: 46136 | U24: 0 | V24: 0 | Z24: gbp_logs
A25: 46013d86-0ba6-4350-a1f0-d604a85a56a7 | B25: Sunny Spa | C25: 46056 | D25: 2026-02 | E25: TRUE | F25: TRUE | G25: TRUE | H25: TRUE | I25: TRUE | J25: TRUE | K25: FALSE | L25: TRUE | M25: TRUE | N25: TRUE | O25: 8 | P25: 7 | Q25: 0 | S25: 46056 | T25: 46103 | U25: 0 | V25: 0 | Z25: gbp
A26: fdbb9826-ab57-479e-9ac1-2bdcaa1ce2d8 | B26: (name not on file) | C26: 46057 | D26: 2026-02 | E26: TRUE | F26: TRUE | G26: TRUE | H26: TRUE | I26: TRUE | J26: FALSE | K26: TRUE | L26: TRUE | M26: TRUE | N26: TRUE | O26: 7 | P26: 5 | Q26: 0 | S26: 46057 | T26: 46057 | U26: 0 | V26: 0 | Z26: unknown
A27: 7f669982-4323-42d1-8e6d-4314a08033bd | B27: Doom Salon | C27: 46057 | D27: 2026-02 | E27: TRUE | F27: TRUE | G27: TRUE | H27: TRUE | I27: TRUE | J27: FALSE | K27: TRUE | L27: TRUE | M27: TRUE | N27: TRUE | O27: 3 | P27: 1 | Q27: 0 | S27: 46057 | T27: 46057 | U27: 0 | V27: 0 | Z27: gbp_logs
A28: f72ac231-6a87-43ef-b01d-60f1ba670cc9 | B28: Natasha super salon | C28: 46057 | D28: 2026-02 | E28: TRUE | F28: TRUE | G28: TRUE | H28: TRUE | I28: TRUE | J28: FALSE | K28: TRUE | L28: TRUE | M28: TRUE | N28: TRUE | O28: 15 | P28: 1 | Q28: 0 | S28: 46057 | T28: 46063 | U28: 2 | V28: 246 | Z28: gbp_logs
A29: 15963e89-bbce-4a40-bb5c-da14dc135e6d | B29: Saxena's spa | C29: 46057 | D29: 2026-02 | E29: TRUE | F29: TRUE | G29: TRUE | H29: TRUE | I29: TRUE | J29: FALSE | K29: TRUE | L29: TRUE | M29: TRUE | N29: TRUE | O29: 0 | P29: 0 | Q29: 0 | U29: 0 | V29: 0 | Z29: gbp_logs
A30: 67e3523d-dff6-47d4-bebf-55bba69ef991 | B30: ponceluxe laser studio | C30: 46058 | D30: 2026-02 | E30: TRUE | F30: TRUE | G30: TRUE | H30: TRUE | I30: TRUE | J30: FALSE | K30: TRUE | L30: TRUE | M30: TRUE | N30: TRUE | O30: 431 | P30: 54 | Q30: 0 | S30: 46058 | T30: 46237 | U30: 1 | V30: 3500 | W30: AzZkqoV5Dtkn82au8 | X30: 100 | Y30: active | Z30: gbp
A31: daf368e0-54b3-4e34-93b0-b2dd15b204d0 | B31: (name not on file) | C31: 46059 | D31: 2026-02 | E31: TRUE | F31: TRUE | G31: TRUE | H31: TRUE | I31: TRUE | J31: FALSE | K31: TRUE | L31: TRUE | M31: TRUE | N31: TRUE | O31: 22 | P31: 15 | Q31: 0 | S31: 46059 | T31: 46059 | U31: 0 | V31: 0 | Z31: unknown
A32: 5b0c1aa0-57c8-469c-a23c-115aa7e6d30e | B32: Shine Salon & Spa | C32: 46059 | D32: 2026-02 | E32: TRUE | F32: TRUE | G32: TRUE | H32: TRUE | I32: TRUE | J32: TRUE | K32: FALSE | L32: TRUE | M32: TRUE | N32: TRUE | O32: 117 | P32: 70 | Q32: 0 | S32: 46059 | T32: 46107 | U32: 36 | V32: 1582.5 | Z32: gbp_logs
A33: 5872c647-324b-43f1-9b1d-b3dc976b9d91 | B33: Nancy's Nail Spa - Best in Bangalore | C33: 46059 | D33: 2026-02 | E33: TRUE | F33: TRUE | G33: TRUE | H33: TRUE | I33: TRUE | J33: FALSE | K33: TRUE | L33: TRUE | M33: TRUE | N33: TRUE | O33: 17 | P33: 14 | Q33: 0 | S33: 46059 | T33: 46120 | U33: 1 | V33: 500 | Z33: gbp_logs
A34: a6d263b8-b099-4c62-b823-9c5f40d1cec8 | B34: (name not on file) | C34: 46059 | D34: 2026-02 | E34: TRUE | F34: TRUE | G34: TRUE | H34: TRUE | I34: TRUE | J34: FALSE | K34: TRUE | L34: TRUE | M34: TRUE | N34: TRUE | O34: 0 | P34: 0 | Q34: 0 | U34: 0 | V34: 0 | Z34: unknown
A35: 08409d6f-f05c-48e9-aef5-1cf77f9de987 | B35: (name not on file) | C35: 46059 | D35: 2026-02 | E35: TRUE | F35: TRUE | G35: TRUE | H35: TRUE | I35: TRUE | J35: FALSE | K35: TRUE | L35: TRUE | M35: TRUE | N35: TRUE | O35: 0 | P35: 0 | Q35: 0 | U35: 0 | V35: 0 | Z35: unknown
A36: 0f4398a1-bb1a-4bff-96fa-e4948216a5a5 | B36: (name not on file) | C36: 46059 | D36: 2026-02 | E36: TRUE | F36: TRUE | G36: TRUE | H36: TRUE | I36: TRUE | J36: FALSE | K36: TRUE | L36: TRUE | M36: TRUE | N36: TRUE | O36: 0 | P36: 0 | Q36: 0 | U36: 0 | V36: 0 | Z36: unknown
A37: f774f9a1-e3df-458b-949f-a1cd9a346214 | B37: Jeans lash lounge | C37: 46059 | D37: 2026-02 | E37: TRUE | F37: TRUE | G37: TRUE | H37: TRUE | I37: TRUE | J37: TRUE | K37: FALSE | L37: TRUE | M37: TRUE | N37: TRUE | O37: 24 | P37: 22 | Q37: 0 | S37: 46059 | T37: 46223 | U37: 0 | V37: 0 | W37: AzqKGMUj2VY405ZFf | X37: 399 | Y37: active | Z37: gbp
A38: bbc01faa-717b-49c6-90f2-ffa50e45af99 | B38: (name not on file) | C38: 46062 | D38: 2026-02 | E38: TRUE | F38: TRUE | G38: TRUE | H38: TRUE | I38: TRUE | J38: FALSE | K38: TRUE | L38: TRUE | M38: TRUE | N38: TRUE | O38: 4 | P38: 4 | Q38: 0 | S38: 46062 | T38: 46063 | U38: 0 | V38: 0 | Z38: unknown
A39: 8516a713-7500-4ad6-9dde-d49f249abbb4 | B39: Lord of Locs | C39: 46062 | D39: 2026-02 | E39: TRUE | F39: TRUE | G39: TRUE | H39: TRUE | I39: TRUE | J39: TRUE | K39: TRUE | L39: TRUE | M39: TRUE | N39: TRUE | O39: 611 | P39: 67 | Q39: 0 | S39: 45465 | T39: 46237 | U39: 72 | V39: 3956 | W39: cus_Q0yzaP9rDqi7TT | X39: 150 | Y39: active | Z39: gbp
A40: db2e88b9-af6a-4d47-8900-9fcca27925a9 | B40: The Beauty Bar Salon and Spa | C40: 46062 | D40: 2026-02 | E40: TRUE | F40: TRUE | G40: TRUE | H40: TRUE | I40: TRUE | J40: TRUE | K40: FALSE | L40: TRUE | M40: TRUE | N40: TRUE | O40: 2623 | P40: 415 | Q40: 0 | S40: 45197 | T40: 46237 | U40: 271 | V40: 8558.5 | W40: cus_OUyjtBRaU7IAeF | X40: 162.94 | Y40: active | Z40: gbp
...

Sheet Cohort Retention
A1: Cohort retention — do accounts keep booking after they switch it on?
A2: Cohort = month the location entered onboarding. Live = took a native booking within 30 days of the as-of date on Summary.
A4: Cohort | B4: Entered | C4: Enabled | D4: Ever booked | E4: Live in last 30d | F4: % of enabled still live
A5: 2026-01 | B5: =SUMPRODUCT(--(Locations!$D$2:$D$445=$A5)) | C5: =SUMPRODUCT(--(Locations!$D$2:$D$445=$A5),--(Locations!$M$2:$M$445=TRUE)) | D5: =SUMPRODUCT(--(Locations!$D$2:$D$445=$A5),--(Locations!$M$2:$M$445=TRUE),--(Locations!$O$2:$O$445>0)) | E5: =SUMPRODUCT(--(Locations!$D$2:$D$445=$A5),--(Locations!$M$2:$M$445=TRUE),--(Locations!$T$2:$T$445>=Summary!$B$3-30)) | F5: =IFERROR(E5/C5,0)
A6: 2026-02 | B6: =SUMPRODUCT(--(Locations!$D$2:$D$445=$A6)) | C6: =SUMPRODUCT(--(Locations!$D$2:$D$445=$A6),--(Locations!$M$2:$M$445=TRUE)) | D6: =SUMPRODUCT(--(Locations!$D$2:$D$445=$A6),--(Locations!$M$2:$M$445=TRUE),--(Locations!$O$2:$O$445>0)) | E6: =SUMPRODUCT(--(Locations!$D$2:$D$445=$A6),--(Locations!$M$2:$M$445=TRUE),--(Locations!$T$2:$T$445>=Summary!$B$3-30)) | F6: =IFERROR(E6/C6,0)
A7: 2026-03 | B7: =SUMPRODUCT(--(Locations!$D$2:$D$445=$A7)) | C7: =SUMPRODUCT(--(Locations!$D$2:$D$445=$A7),--(Locations!$M$2:$M$445=TRUE)) | D7: =SUMPRODUCT(--(Locations!$D$2:$D$445=$A7),--(Locations!$M$2:$M$445=TRUE),--(Locations!$O$2:$O$445>0)) | E7: =SUMPRODUCT(--(Locations!$D$2:$D$445=$A7),--(Locations!$M$2:$M$445=TRUE),--(Locations!$T$2:$T$445>=Summary!$B$3-30)) | F7: =IFERROR(E7/C7,0)
A8: 2026-04 | B8: =SUMPRODUCT(--(Locations!$D$2:$D$445=$A8)) | C8: =SUMPRODUCT(--(Locations!$D$2:$D$445=$A8),--(Locations!$M$2:$M$445=TRUE)) | D8: =SUMPRODUCT(--(Locations!$D$2:$D$445=$A8),--(Locations!$M$2:$M$445=TRUE),--(Locations!$O$2:$O$445>0)) | E8: =SUMPRODUCT(--(Locations!$D$2:$D$445=$A8),--(Locations!$M$2:$M$445=TRUE),--(Locations!$T$2:$T$445>=Summary!$B$3-30)) | F8: =IFERROR(E8/C8,0)
A9: 2026-05 | B9: =SUMPRODUCT(--(Locations!$D$2:$D$445=$A9)) | C9: =SUMPRODUCT(--(Locations!$D$2:$D$445=$A9),--(Locations!$M$2:$M$445=TRUE)) | D9: =SUMPRODUCT(--(Locations!$D$2:$D$445=$A9),--(Locations!$M$2:$M$445=TRUE),--(Locations!$O$2:$O$445>0)) | E9: =SUMPRODUCT(--(Locations!$D$2:$D$445=$A9),--(Locations!$M$2:$M$445=TRUE),--(Locations!$T$2:$T$445>=Summary!$B$3-30)) | F9: =IFERROR(E9/C9,0)
A10: 2026-06 | B10: =SUMPRODUCT(--(Locations!$D$2:$D$445=$A10)) | C10: =SUMPRODUCT(--(Locations!$D$2:$D$445=$A10),--(Locations!$M$2:$M$445=TRUE)) | D10: =SUMPRODUCT(--(Locations!$D$2:$D$445=$A10),--(Locations!$M$2:$M$445=TRUE),--(Locations!$O$2:$O$445>0)) | E10: =SUMPRODUCT(--(Locations!$D$2:$D$445=$A10),--(Locations!$M$2:$M$445=TRUE),--(Locations!$T$2:$T$445>=Summary!$B$3-30)) | F10: =IFERROR(E10/C10,0)
A11: 2026-07 | B11: =SUMPRODUCT(--(Locations!$D$2:$D$445=$A11)) | C11: =SUMPRODUCT(--(Locations!$D$2:$D$445=$A11),--(Locations!$M$2:$M$445=TRUE)) | D11: =SUMPRODUCT(--(Locations!$D$2:$D$445=$A11),--(Locations!$M$2:$M$445=TRUE),--(Locations!$O$2:$O$445>0)) | E11: =SUMPRODUCT(--(Locations!$D$2:$D$445=$A11),--(Locations!$M$2:$M$445=TRUE),--(Locations!$T$2:$T$445>=Summary!$B$3-30)) | F11: =IFERROR(E11/C11,0)
A12: TOTAL | B12: =SUM(B5:B11) | C12: =SUM(C5:C11) | D12: =SUM(D5:D11) | E12: =SUM(E5:E11) | F12: =IFERROR(E12/C12,0)
A14: Every settled cohort lands at roughly 20-25% still booking. July looks healthy only because it just onboarded — it has not aged yet. This is a retention problem, not a conversion problem.

Sheet Bookings and Revenue
A1: Bookings, payments and displaced incumbents
A3: VALUE PROCESSED
A4: Metric | B4: Value | C4: Source
A5: Completed payments (USD) | B5: =SUM(Locations!$V$2:$V$445) | C5: Locations sheet, col U
A6: Completed transactions | B6: =SUM(Locations!$U$2:$U$445) | C6: Locations sheet, col T
A7: Accounts that processed a payment | B7: =SUMPRODUCT(--(Locations!$U$2:$U$445>0)) | C7: Locations sheet
A8: Native bookings | B8: =SUM(Locations!$O$2:$O$445) | C8: Excludes migrated history
A9: Customer self-serve bookings | B9: =SUM(Locations!$P$2:$P$445) | C9: created_by_type EC or CLIENT
A10: Migrated (historical) bookings | B10: =SUM(Locations!$Q$2:$Q$445) | C10: Imported, not earned
A12: BOOKING CREATOR MIX — all bookings, from scheduling.bookings
A13: Hardcoded. Source: scheduling.bookings grouped by created_by_type and migration_source, queried 03/08/26.
A14: Creator type | B14: Bookings | C14: Accounts | D14: Meaning
A15: SP — staff-made | B15: 11028 | C15: 197 | D15: Business enters the booking
A16: SYSTEM — automated | B16: 7091 | C16: 4
A17: EC — end customer self-serve | B17: 4352 | C17: 247 | D17: The number that proves the product works
A18: CLIENT — client app | B18: 260 | C18: 31
A19: MCP — agent | B19: 48 | C19: 12
A20: MIGRATION — native flag | B20: 240 | C20: 1
A22: INCUMBENT SYSTEMS MIGRATED FROM
A23: Hardcoded. Source: scheduling.bookings.migration_source, queried 03/08/26. Only 14 accounts imported history — the rest either had nothing to move or never fully switched.
A24: Prior system | B24: Bookings migrated | C24: Accounts
A25: Zoca internal ops | B25: 15756 | C25: 2
A26: Square | B26: 7748 | C26: 4
A27: Vagaro | B27: 6321 | C27: 1
A28: Fresha | B28: 4984 | C28: 1
A29: Booksy | B29: 4088 | C29: 1
A30: GlossGenius | B30: 3978 | C30: 1
A31: Acuity | B31: 3338 | C31: 4
A32: Setmore | B32: 1158 | C32: 1
A33: GoDaddy | B33: 56 | C33: 2
A35: RECONCILIATION — why this sheet says $632,036 and the written report says $645,568
A36: This workbook aggregates the 444 locations in scheduling.onboarding. scheduling.payments contains one further paying entity with no onboarding record, worth $13,532 across 1 account. All-entity truth: $645,568.21 / 6,061 completed transactions / 139 accounts. Neither figure is wrong; they have different denominators. Quote the all-entity number externally and this one when working from these sheets.

Sheet Objection Themes
A1: Why accounts did not convert
A2: Two classes of evidence. The mechanical evidence is reliable. The stated evidence is directional only.
A4: MECHANICAL — proven by the funnel
A5: Finding | B5: Value | C5: Why it matters
A6: Locations that skipped payment setup | B6: =SUMPRODUCT(--(Locations!$K$2:$K$445=TRUE)) | C6: No deposits, no no-show fees. An account without payments is running a diary, and a diary loses to the incumbent.
A7: Locations that configured payments | B7: =SUMPRODUCT(--(Locations!$J$2:$J$445=TRUE))
A8: Enabled but never took a booking | B8: =SUMPRODUCT(--(Locations!$M$2:$M$445=TRUE),--(Locations!$O$2:$O$445=0)) | C8: Completed every setup step, then did nothing. Setup completion is being mistaken for adoption.
A9: Enabled but dormant (no booking in 30d) | B9: =SUMPRODUCT(--(Locations!$M$2:$M$445=TRUE),--(Locations!$T$2:$T$445<Summary!$B$3-30))
A10: Accounts that imported history from a rival | B10: =SUMPRODUCT(--(Locations!$R$2:$R$445<>"")) | C10: Only this many actually moved their history across.
A13: STATED — topic prevalence across 1,829 scheduling calls, 01/11/25 to 03/08/26
A14: Hardcoded. Source: regex over sales.fireflies_meeting.summary, queried 03/08/26. CAUTION: these calls carry no entity_id, so these reasons CANNOT be counted per account. Do not present as 'N accounts said X'.
A15: Topic | B15: Calls | C15: Share of 1,829 | D15: Comment
A16: Deferred / 'not right now' | B16: 441 | C16: =B16/1829
A17: Migration or data-transfer effort | B17: 247 | C17: =B17/1829
A18: Payments, deposits, no-show fees | B18: 227 | C18: =B18/1829 | D18: Matches the mechanical finding above
A19: Contract / lock-in language | B19: 215 | C19: =B19/1829 | D19: Noisy — 'contract' matches loosely
A20: Named an incumbent competitor | B20: 303 | C20: =B20/1829 | D20: The reliable signal
A21: Explicit refusal language | B21: 174 | C21: =B21/1829
A22: Prefers phone / walk-in / manual | B22: 119 | C22: =B22/1829
A23: Price or budget | B23: 69 | C23: =B23/1829
A24: Staff resistance or complexity | B24: 42 | C24: =B24/1829
A26: INCUMBENTS NAMED IN CALL SUMMARIES
A27: Hardcoded, same source. Square is inflated — the word matches non-product uses. Treat Vagaro, Booksy, Mindbody and Fresha as the reliable signals.
A28: Competitor | B28: Calls naming it
A29: Square (inflated) | B29: 269
A30: Vagaro | B30: 105
A31: Booksy | B31: 46
A32: Mindbody | B32: 39
A33: Fresha | B33: 35
A34: Acuity | B34: 26
A35: StyleSeat | B35: 11
A36: GlossGenius | B36: 11
A37: Boulevard / Phorest / Setmore / Schedulicity | B37: 43
A39: THEMES VERIFIED BY READING CALL EXCERPTS BY HAND
A40: • Feature gaps keep the old system alive — staff revenue and commission reporting, clock-in/out, staff permission levels, calendar column-per-staff view, selective client blocking, package and membership migration, intake forms.
A41: • Payment processor economics — Stripe rates raised as a negotiation point rather than accepted.
A42: • Base subscription price — $149/month cited as unaffordable by an account under budget freeze. A whole-platform objection, not a scheduling one.
A43: • Rollback on confusion — at least one account asked for the booking system to be revoked 'to reduce confusion and inefficiency' after enabling it.
A44: • Free is the wedge that works — where the pitch replaces a paid incumbent at no cost, it lands. Cost displacement is the strongest observed motivator.

Sheet Instrumentation Gaps
A1: Where a pitch record should live, and what is actually there
A2: This is the finding underneath the finding: the pitch is recoverable by archaeology, but it is not recorded.
A4: System / table | B4: What is actually there | C4: Consequence
A5: cx.upsell_potential | B5: Covers only the five AI agents (ADS, WIN, LOYALTY, SOCIAL, DISCOVERY). No scheduling row. Stops 12/01/26. All 3,124 rows status POTENTIAL, upsold_amount = 0 on every row. | C5: No upsell tracking for scheduling at all
A6: sales.customer_meetings.product | B6: Null on 11,113 of 11,128 rows (99.9%). The 15 populated rows are May 2025 only. | C6: Cannot tell which product a meeting was about
A7: sales.fireflies_meeting.entity_id | B7: Populated on 431 of 22,242 rows (1.9%). | C7: Useless as a join key — attribution had to go via participant email instead
A8: cx.open_issues / cx.churn_potential | B8: Both stop writing 14/01/26 — two weeks BEFORE scheduling launched. | C8: The qualitative feed went dark at the worst possible moment
A9: offboarding.reason_template_mapping | B9: 30 rows total, exactly 5 per reason. | C9: A seeded template list, not collected data
A10: Chargebee catalogue | B10: No scheduling SKU. Closest items are Booking-Agent, Lead-to-Booking, FrontDesk. | C10: Scheduling is bundled, so billing shows no adoption signal
A11: scheduling.onboarding.entity_id | B11: Zero overlap with bookings or Chargebee. The account key is location_entity_id. | C11: A join on entity_id returns a valid-looking all-zero result rather than an error
A13: TO MAKE THIS ANSWERABLE WITHOUT ARCHAEOLOGY
A14: Priority | B14: Action | C14: Why
A15: 1 | B15: Add pitched_at / pitched_by / pitch_outcome / decline_reason to the scheduling onboarding record, set when an AM makes the offer | C15: Without it every future version of this question needs a month of transcript work
A16: 2 | B16: Backfill entity_id on Fireflies rows from participants email | C16: 98% of call intelligence is currently unattributable; this unlocks it retrospectively and makes the pitch a live metric
A17: 3 | B17: Find out why cx.open_issues and cx.churn_potential stopped writing on 14/01/26 | C17: Two account-health tables going dark together is either a broken job or a decommissioned pipeline
A18: 4 | B18: Instrument dormancy, not setup | C18: 'Scheduling enabled' is the visible metric; 'booked in the last 30 days' is the one that matters and is 2.5x smaller
