Workbook

Sheet README
A1: Scheduling — pitch, adoption and retention (v3, validated 04/08/26)
A4: Version | B4: v3 — 04/08/26. Pitch window widened to all months (median conversion lag is 35 days, so a single-month window understates). Adoption sheets rebuilt on 178 LEGITIMATE locations after removing 237 is_test and 29 is_active=FALSE entities. Payments date-filtered to post-launch. Pitch register screened for test entities: zero contamination.
A5: Definitions contract | B5: docs/scheduling-metric-definitions.md — every term here has one meaning. Read it before quoting anything.
A6: As-of date | B6: 03/08/26. Launch date 30/01/26. All trailing-window tests run off the as-of cell on Summary.
A7: Source | B7: Aurora via Metabase DB 7 — scheduling.*, chargebee.*, sales.fireflies_meeting, gbp.*, entities.*
A9: HEADLINE
A10: Accounts pitched (Nov 25 - Aug 26) | B10: 148 (133 still active)
A11: …reached scheduling enabled | B11: 23 onboarded to enabled; 23 taking bookings; median 35-day lag
A12: …never started onboarding | B12: 50 (79%)
A13: Legitimate locations in adoption sheets | B13: 178 (raw table holds 446; 237 are is_test, 29 inactive, 4 unverifiable)
A14: Locations enabled (config flag) | B14: 140
A15: Locations still booking in last 30d | B15: 112
A16: Value processed through scheduling | B16: $249,919 across the 178 legitimate locations; $328,021 platform-wide post-launch
A17: Customer-made bookings since launch | B17: 4,627 — zero pre-launch contamination; the cleanest proof the product works
A19: WHAT V1 GOT WRONG
A20: Pitch count 98 → 63 | B20: The offer regex had no word boundary, so 'our booking platform' also matched 'y-OUR booking platform'. Reps discussing the customer's EXISTING system were counted as Zoca pitches — 55% false positives on a 22-call sample. Fixed with \mour.
A21: Conversion 15 → 8 | B21: Same cause, plus counting per Chargebee customer record. 2,026 records hold 1,799 distinct emails; 89 emails map to multiple records. v2 resolves to entity_id.
A22: Native bookings 23,019 → 9,605 | B22: 'migration_source IS NULL' does NOT mean earned on Zoca. 33 entities had history imported with no migration tag; 13,266 bookings predated launch. v2 counts only bookings created between 30/01/26 and the as-of date.
A23: 'Ever booked' 279 vs 286 | B23: v1 gave the same label to two different populations on two sheets (one conditioned on the enabled flag, one not). v2 uses 'Operationally live' everywhere and the sheets reconcile exactly.
A24: Cohort footnote | B24: v1 claimed 'every settled cohort lands at 20-25%'. Only one of six cohorts did. Removed.
A26: DEFINITIONS THAT MATTER MOST
A27: Earned booking | B27: migration_source IS NULL AND created_at between 30/01/26 and the as-of date. Excludes untagged imported history and 351 future-dated rows.
A28: Customer-made booking | B28: Earned AND created_by_type in ('EC','CLIENT'). The figure that proves demand.
A29: Enabled (flag) | B29: is_scheduling_enabled = TRUE. A CONFIGURATION flag and it is unreliable — 7 locations took real bookings while flagged FALSE. Use for setup progress only.
A30: Operationally live | B30: Has at least one earned booking, regardless of the flag. Use this for 'is it actually being used'.
A31: Live in last 30d | B31: Most recent EARNED booking within 30 days of the as-of date.
A32: Location vs account | B32: 444 locations map to 270 Chargebee customers of any status and 156 active ones. Never quote 444 as an account count.
A34: COVERAGE LIMITS — STATE THESE WITH THE NUMBER
A35: 63 is a floor | B35: Only accounts whose call attendee email matches a Chargebee customer are counted; roughly half of external emails match.
A36: Prospects excluded | B36: Pitched emails matching no customer record are new-business pitches, not upsells, and are out of scope.
A37: Attribution is temporal | B37: An onboarding record created after the call is attributed to the pitch. Reasonable in a one-month window; not proven.
A38: Live data | B38: Aurora is queried live and grew during this session. Figures are as at 03/08/26.
A40: SHEET GUIDE
A41: Summary | B41: Headline metrics, all calculated
A42: July Pitch Funnel | B42: 1,051 calls narrowed to 63 pitched accounts
A43: Pitched Accounts | B43: 74 rows = 63 pitched + 11 already-live (flagged col H). Column F links to the call.
A44: Adoption Funnel | B44: All 444 locations, stage by stage
A45: Locations | B45: Per-location detail, business name in column B
A46: Cohort Retention | B46: Monthly cohorts — same definitions as Adoption Funnel, so totals reconcile
A47: Bookings and Revenue | B47: Earned vs pre-launch vs migrated, payments, incumbents
...

Sheet Summary
A1: Summary — v2 corrected
A3: As-of date (drives every trailing-window test) | B3: =DATE(2026,8,3) | C3: Blue = input. Change this one cell to re-date the whole workbook.
A5: PITCH — ALL MONTHS (Nov 25 – Aug 26) | B5: Value | C5: Definition / note
A6: Accounts pitched (all months) | B6: =COUNTA('Pitch Register'!$A$16:$A$163) | C6: Offer made, not already live when pitched. All months Nov 25 - Aug 26.
A7: …started onboarding after the pitch | B7: =SUMPRODUCT(--('Pitch Register'!$E$16:$E$163<>"")) | C7: Median 35 days after the pitch; 16 of 31 took over 30 days
A8: …reached Enabled (flag) | B8: =SUMPRODUCT(--('Pitch Register'!$G$16:$G$163=TRUE)) | C8: The conversion number
A9: …operationally live (has earned bookings) | B9: =SUMPRODUCT(--('Pitch Register'!$I$16:$I$163>0)) | C9: Actually taking bookings
A10: …never started onboarding | B10: =SUMPRODUCT(--('Pitch Register'!$E$16:$E$163=""))
A11: Pitch-to-activation rate | B11: =B8/B6 | C11: Enabled ÷ pitched
A12: Excluded — already live at pitch | B12: 25 | C12: Static: excluded by construction, not present in the Pitch Register
A14: ADOPTION — 178 LEGITIMATE LOCATIONS | B14: Value | C14: Definition / note
A15: Locations entered onboarding | B15: =COUNTA(Locations!$A$2:$A$445) | C15: LOCATIONS, not accounts
A16: Enabled (config flag) | B16: =SUMPRODUCT(--(Locations!$M$2:$M$445=TRUE)) | C16: Setup progress only — flag is unreliable
A17: Operationally live (≥1 earned booking) | B17: =SUMPRODUCT(--(Locations!$X$2:$X$445=TRUE)) | C17: The honest 'is it used' measure
A18: Live in last 30 days | B18: =SUMPRODUCT(--(Locations!$W$2:$W$445>=$B$3-30)) | C18: Most recent EARNED booking within 30d
A19: Dormant (live once, not in last 30d) | B19: =B16-B17 | C19: The core finding
A20: Dormant share of operationally live | B20: =B18/B16
A21: Payments configured | B21: =SUMPRODUCT(--(Locations!$J$2:$J$445=TRUE))
A22: Payments explicitly skipped | B22: =SUMPRODUCT(--(Locations!$K$2:$K$445=TRUE)) | C22: The single biggest structural break
A23: Locations linked to a billed account | B23: =SUMPRODUCT(--(Locations!$AB$2:$AB$445<>"")) | C23: 444 locations ≠ 444 accounts
A25: VALUE AND VOLUME | B25: Value | C25: Definition / note
A26: Earned bookings since launch | B26: =SUM(Locations!$O$2:$O$445) | C26: Excludes untagged pre-launch history and future-dated
A27: Customer-made bookings | B27: =SUM(Locations!$P$2:$P$445) | C27: Zero pre-launch contamination — the cleanest proof of demand
A28: Staff-made bookings | B28: =SUM(Locations!$Q$2:$Q$445)
A29: Pre-launch untagged (EXCLUDED) | B29: =SUM(Locations!$R$2:$R$445) | C29: Imported history with no migration_source tag — v1 counted these as organic
A30: Tagged migration (EXCLUDED) | B30: =SUM(Locations!$S$2:$S$445) | C30: Square, Vagaro, Fresha, Booksy, GlossGenius, Acuity, Setmore, GoDaddy
A31: Value processed (USD) | B31: =SUM(Locations!$AA$2:$AA$445) | C31: POST-LAUNCH only (created >= 30/01/26). All-time incl. pre-launch history is $646,104 — not product value.
A32: Locations that processed a payment | B32: =SUMPRODUCT(--(Locations!$Z$2:$Z$445>0))

Sheet Pitch Register
A1: Pitch register — every recorded pitch, Nov 2025 to Aug 2026
A2: One row per account, dated by its FIRST recorded pitch. Conversion takes a median of 35 days, so recent months are still maturing — do not judge a pitch month before ~90 days.
A4: Accounts PITCHED | B4: 148 | C4: Offer made on a recorded call; not already using scheduling
A5: …onboarded after the pitch | B5: 31 | C5: Median 35 days later — 16 of 31 took over 30 days
A6: …reached enabled | B6: 23 | C6: Scheduling switched on
A7: …taking bookings | B7: 23 | C7: Actually receiving bookings — the real conversion
A8: …live in last 30 days | B8: 22 | C8: Still receiving bookings now
A9: NEVER onboarded | B9: 117 | C9: 15 of these have since churned; none of the 15 ever converted
A10: Excluded — already live when pitched | B10: 25 | C10: Offer language to an existing user = support, not a pitch
A11: Bookings from converted accounts | B11: 1584 | C11: Total taken by the 31 that onboarded
A12: …customer-made | B12: 407 | C12: Booked by the end customer, not staff
A13: Payments post-launch, converted | B13: 194993.61 | C13: Processed by those accounts since 30/01/26
A15: Business | B15: Contact | C15: Pitch month | D15: First pitched | E15: Onboarded | F15: Days pitch→onboard | G15: Enabled | H15: Payments set | I15: Earned bookings | J15: Customer-made | K15: Last booking | L15: Payments (USD) | M15: Outcome | N15: Pitch call | O15: Account still active
A16: Deka Lash | B16: amaiti@dekalash.com | C16: 2025-11 | D16: 45989 | G16: FALSE | H16: FALSE | I16: 0 | J16: 0 | L16: 0 | M16: Never onboarded | N16: Follow-up Call X Zoca | O16: TRUE
A17: All Aesthetics Kare | B17: info@allaestheticskare.com | C17: 2025-11 | D17: 45972 | G17: FALSE | H17: FALSE | I17: 0 | J17: 0 | L17: 0 | M17: Never onboarded | N17: Yarira Preston and Shipra Shreya from ZOCA | O17: TRUE
A18: Headquarters Hair Care | B18: kdpitman40@hotmail.com | C18: 2025-12 | D18: 46022 | E18: 46204 | F18: 182 | G18: FALSE | H18: FALSE | I18: 149 | J18: 0 | K18: 46235 | L18: 0 | M18: Booking | N18: Headquarters Hair Care X Zoca | Check In Dece | O18: TRUE
A19: Niks Lash NYC | B19: bandanasewa9@gmail.com | C19: 2025-12 | D19: 45993 | G19: FALSE | H19: FALSE | I19: 0 | J19: 0 | L19: 0 | M19: Never onboarded | N19: Bandana Sewa X Zoca | Check In December | O19: TRUE
A20: Urban Shave | B20: urbanshavellc@gmail.com | C20: 2025-12 | D20: 46000 | G20: FALSE | H20: FALSE | I20: 0 | J20: 0 | L20: 0 | M20: Never onboarded | N20: Urban Shave X Zoca | Check In December | O20: TRUE
A21: Sumathy Reddy, M.D. | B21: sumathyreddy@mail.com | C21: 2025-12 | D21: 46001 | G21: FALSE | H21: FALSE | I21: 0 | J21: 0 | L21: 0 | M21: Never onboarded | N21: Zoca Check-in | Sumathy Reddy, M.D. | O21: FALSE
A22: Hydra-Bar Salon | B22: info@hydrabarsalon.com | C22: 2025-12 | D22: 45994 | G22: FALSE | H22: FALSE | I22: 0 | J22: 0 | L22: 0 | M22: Never onboarded | N22: Hydra Bar X Zoca | Check In December | O22: TRUE
A23: Elva Medical Aesthetics | B23: elvabeautyy@gmail.com | C23: 2025-12 | D23: 45993 | G23: FALSE | H23: FALSE | I23: 0 | J23: 0 | L23: 0 | M23: Never onboarded | N23: Elva Beauty Inc. X Zoca | Check In December | O23: TRUE
A24: Les Ciseaux Salon and Spa | B24: lesciseaux@gmail.com | C24: 2025-12 | D24: 45994 | G24: FALSE | H24: FALSE | I24: 0 | J24: 0 | L24: 0 | M24: Never onboarded | N24: Les Ciseaux Salon & Spa X Zoca | Check In Nov | O24: TRUE
A25: Beverly Dentistry | B25: beverlydental1@gmail.com | C25: 2025-12 | D25: 46010 | G25: FALSE | H25: FALSE | I25: 0 | J25: 0 | L25: 0 | M25: Never onboarded | N25: Beverly Gonzales and Bikash Chandra | O25: TRUE
A26: VPRO Beauty Salon & Spa | B26: vprospa@gmail.com | C26: 2025-12 | D26: 46017 | G26: FALSE | H26: FALSE | I26: 0 | J26: 0 | L26: 0 | M26: Never onboarded | N26: VPRO Beauty Salon & Spa X Zoca | Check In Dec | O26: TRUE
A27: Mad Men Groom-In Room | B27: alvis.hamilton72@yahoo.com | C27: 2025-12 | D27: 46002 | G27: FALSE | H27: FALSE | I27: 0 | J27: 0 | L27: 0 | M27: Never onboarded | N27: Alvis and Kanak Sharma | O27: TRUE
A28: Donna Skin and Body Care | B28: donna.skin@gmail.com | C28: 2026-01 | D28: 46034 | E28: 46169 | F28: 135 | G28: TRUE | H28: TRUE | I28: 105 | J28: 6 | K28: 46237 | L28: 0 | M28: Booking | N28: Donna Skin and Body Care X Zoca | Check In Ja | O28: TRUE
A29: Adel braids | B29: adelbih76@gmail.com | C29: 2026-01 | D29: 46049 | E29: 46066 | F29: 17 | G29: TRUE | H29: TRUE | I29: 19 | J29: 17 | K29: 46220 | L29: 396 | M29: Booking | N29: Zoca X Adel Braids | O29: TRUE
A30: Michael's Salon | B30: baturov11@gmail.com | C30: 2026-01 | D30: 46042 | E30: 46223 | F30: 181 | G30: TRUE | H30: FALSE | I30: 1 | J30: 1 | K30: 46235 | L30: 0 | M30: Booking | N30: Irina Khaimova and Hubern | O30: TRUE
A31: BB Meme Salon Hillcrest | B31: bbmemesalon@gmail.com | C31: 2026-01 | D31: 46034 | E31: 46224 | F31: 190 | G31: TRUE | H31: FALSE | I31: 0 | J31: 0 | L31: 0 | M31: Enabled, no bookings | N31: bbmeme and Shikha | O31: TRUE
A32: Sugar Me Waxing Studio | B32: smwstudio@gmail.com | C32: 2026-01 | D32: 46037 | G32: FALSE | H32: FALSE | I32: 0 | J32: 0 | L32: 0 | M32: Never onboarded | N32: Sugar Me Waxing Studio X Zoca | Check In Janu | O32: TRUE
A33: IM=X Pilates and Fitness Mansfield | B33: michelle@imxpilates.com | C33: 2026-01 | D33: 46052 | G33: FALSE | H33: FALSE | I33: 0 | J33: 0 | L33: 0 | M33: Never onboarded | N33: IM=X Pilates and Fitness Mansfield X Zoca | C | O33: TRUE
A34: Rosy Tips Nail Salon Chula Vista CA | B34: rosytipsnailsnspa@gmail.com | C34: 2026-01 | D34: 46042 | G34: FALSE | H34: FALSE | I34: 0 | J34: 0 | L34: 0 | M34: Never onboarded | N34: Linh Nguyen and Shikha | O34: TRUE
A35: Lashes & Body on Fleek LLC | B35: lashesonfleekllc@gmail.com | C35: 2026-01 | D35: 46031 | G35: FALSE | H35: FALSE | I35: 0 | J35: 0 | L35: 0 | M35: Never onboarded | N35: Founder Connect |Lashes & Body on Fleek LLC | O35: TRUE
A36: The Wow Studio | B36: info@thewowstudio.net | C36: 2026-01 | D36: 46048 | G36: FALSE | H36: FALSE | I36: 0 | J36: 0 | L36: 0 | M36: Never onboarded | N36: The WOW Studio X ZOCA | Check-in Call | O36: TRUE
A37: InVein Aesthetics | B37: shawnta@inveinspa.com | C37: 2026-01 | D37: 46030 | G37: FALSE | H37: FALSE | I37: 0 | J37: 0 | L37: 0 | M37: Never onboarded | N37: Shawnta <> Check - in | O37: TRUE
A38: Bella Luna - Lash and Brow Boutique | B38: threadingbylinet@yahoo.com | C38: 2026-01 | D38: 46041 | G38: FALSE | H38: FALSE | I38: 0 | J38: 0 | L38: 0 | M38: Never onboarded | N38: Linet Haratunian and Shikha | O38: TRUE
A39: Lash and Skin Studio | B39: erica.business14@gmail.com | C39: 2026-01 | D39: 46042 | G39: FALSE | H39: FALSE | I39: 0 | J39: 0 | L39: 0 | M39: Never onboarded | N39: Check in Call X Lash and skin studio | O39: TRUE
A40: ConcreteWood Studio | B40: junjie.du1010@gmail.com | C40: 2026-01 | D40: 46052 | G40: FALSE | H40: FALSE | I40: 0 | J40: 0 | L40: 0 | M40: Never onboarded | N40: Jun jie du and Atharv Yadav | O40: FALSE
A41: Lash Wonderland | Eyelash | Facial | Brow | Lash Lift | B41: lashwonderlandnyc@gmail.com | C41: 2026-01 | D41: 46042 | G41: FALSE | H41: FALSE | I41: 0 | J41: 0 | L41: 0 | M41: Never onboarded | N41: sophie and Shikha | O41: FALSE
A42: Emporio African Braids | B42: ayanniyitemitope10@gmail.com | C42: 2026-02 | D42: 46063 | E42: 46065 | F42: 2 | G42: TRUE | H42: TRUE | I42: 67 | J42: 57 | K42: 46237 | L42: 1803.6 | M42: Booking | N42: Temmy <> Check - in | O42: TRUE
...

Sheet Adoption Funnel
A1: Scheduling adoption funnel — 178 legitimate locations
A2: Test and inactive entities removed. Earlier versions showed 444, of which 237 were is_test=TRUE. Every count calculates from the Locations sheet.
A4: Stage | B4: Locations | C4: % of entered | D4: Reading
A5: Entered onboarding | B5: =COUNTA(Locations!$A$2:$A$179) | C5: =B5/$B$5 | D5: Denominator — legitimate only
A6: Opted in | B6: =SUMPRODUCT(--(Locations!$E$2:$E$179=TRUE)) | C6: =B6/$B$5
A7: Business details set | B7: =SUMPRODUCT(--(Locations!$F$2:$F$179=TRUE)) | C7: =B7/$B$5
A8: Services configured | B8: =SUMPRODUCT(--(Locations!$G$2:$G$179=TRUE)) | C8: =B8/$B$5
A9: Booking rules configured | B9: =SUMPRODUCT(--(Locations!$H$2:$H$179=TRUE)) | C9: =B9/$B$5
A10: Booking policies configured | B10: =SUMPRODUCT(--(Locations!$I$2:$I$179=TRUE)) | C10: =B10/$B$5
A11: Website flipped to Zoca booking | B11: =SUMPRODUCT(--(Locations!$N$2:$N$179=TRUE)) | C11: =B11/$B$5
A12: Onboarding completed | B12: =SUMPRODUCT(--(Locations!$L$2:$L$179=TRUE)) | C12: =B12/$B$5
A13: Enabled (config flag) | B13: =SUMPRODUCT(--(Locations!$M$2:$M$179=TRUE)) | C13: =B13/$B$5 | D13: SETUP conversion
A14: Payments configured | B14: =SUMPRODUCT(--(Locations!$J$2:$J$179=TRUE)) | C14: =B14/$B$5 | D14: The wall
A15: Payments explicitly skipped | B15: =SUMPRODUCT(--(Locations!$K$2:$K$179=TRUE)) | C15: =B15/$B$5 | D15: The wall
A16: Operationally live (>=1 earned booking) | B16: =SUMPRODUCT(--(Locations!$T$2:$T$179=TRUE)) | C16: =B16/$B$5 | D16: ACTIVATION conversion
A17: …took a customer-made booking | B17: =SUMPRODUCT(--(Locations!$P$2:$P$179>0)) | C17: =B17/$B$5
A18: Live in last 90 days | B18: =SUMPRODUCT(--(Locations!$S$2:$S$179>=Summary!$B$3-90)) | C18: =B18/$B$5
A19: Live in last 30 days | B19: =SUMPRODUCT(--(Locations!$S$2:$S$179>=Summary!$B$3-30)) | C19: =B19/$B$5 | D19: SUSTAINED conversion

Sheet Locations
A1: Location entity id | B1: Business name | C1: Onboarding started | D1: Cohort | E1: Opted in | F1: Business details | G1: Services configured | H1: Booking rules | I1: Booking policies | J1: Payments configured | K1: Payments skipped | L1: Onboarding completed | M1: Enabled (flag) | N1: Website flipped | O1: Earned bookings | P1: Customer-made | Q1: Staff-made | R1: Migration source | S1: Last earned booking | T1: Operationally live | U1: Live in last 30d | V1: Paid transactions | W1: Paid amount post-launch (USD) | X1: Chargebee customer id | Y1: MRR (USD) | Z1: Subscription status
A2: f2930e96-c10f-4273-834d-948790dcb785 | B2: Nbraidstyles | C2: 46052 | D2: 2026-01 | E2: TRUE | F2: TRUE | G2: TRUE | H2: TRUE | I2: TRUE | J2: TRUE | K2: FALSE | L2: TRUE | M2: TRUE | N2: TRUE | O2: 75 | P2: 73 | Q2: 2 | S2: 46237 | T2: TRUE | U2: TRUE | V2: 69 | W2: 2627 | X2: cus_OGiPoqL0Cu6SL2 | Y2: 135 | Z2: active
A3: 0a3e4ac6-9bdb-4e76-b354-7e2f2d6bb72c | B3: (name not on file) | C3: 46053 | D3: 2026-01 | E3: TRUE | F3: TRUE | G3: FALSE | H3: FALSE | I3: FALSE | J3: FALSE | K3: FALSE | L3: FALSE | M3: FALSE | N3: FALSE | O3: 0 | P3: 0 | Q3: 0 | T3: FALSE | U3: FALSE | V3: 0 | W3: 0
A4: d1983fab-fb1b-43c6-af50-2e25684bdc16 | B4: (name not on file) | C4: 46053 | D4: 2026-01 | E4: TRUE | F4: TRUE | G4: TRUE | H4: TRUE | I4: TRUE | J4: FALSE | K4: TRUE | L4: TRUE | M4: TRUE | N4: TRUE | O4: 5 | P4: 0 | Q4: 5 | S4: 46053 | T4: TRUE | U4: FALSE | V4: 0 | W4: 0
A5: 61bcfc8a-d56d-4b46-a4a3-658ce60aa48f | B5: (name not on file) | C5: 46053 | D5: 2026-01 | E5: TRUE | F5: TRUE | G5: TRUE | H5: TRUE | I5: TRUE | J5: FALSE | K5: TRUE | L5: TRUE | M5: TRUE | N5: TRUE | O5: 3 | P5: 0 | Q5: 3 | S5: 46055 | T5: TRUE | U5: FALSE | V5: 0 | W5: 0
A6: 07233b3c-c922-40a7-8ac3-e57986ffb675 | B6: (name not on file) | C6: 46055 | D6: 2026-02 | E6: TRUE | F6: TRUE | G6: TRUE | H6: TRUE | I6: TRUE | J6: FALSE | K6: TRUE | L6: TRUE | M6: TRUE | N6: TRUE | O6: 17 | P6: 9 | Q6: 8 | S6: 46056 | T6: TRUE | U6: FALSE | V6: 0 | W6: 0
A7: 736264eb-3de6-49d0-a1fb-6706edc2ac61 | B7: Creations Art and Beauty | C7: 46055 | D7: 2026-02 | E7: TRUE | F7: TRUE | G7: TRUE | H7: TRUE | I7: TRUE | J7: TRUE | K7: FALSE | L7: TRUE | M7: TRUE | N7: TRUE | O7: 23 | P7: 12 | Q7: 11 | S7: 46233 | T7: TRUE | U7: TRUE | V7: 1 | W7: 1.4 | X7: AzqhpEUzYFk7hC0ut | Y7: 350 | Z7: active
A8: 410b7b26-6680-425d-8f37-642290a08d52 | B8: (name not on file) | C8: 46056 | D8: 2026-02 | E8: TRUE | F8: TRUE | G8: TRUE | H8: TRUE | I8: TRUE | J8: FALSE | K8: TRUE | L8: TRUE | M8: TRUE | N8: TRUE | O8: 14 | P8: 8 | Q8: 6 | S8: 46057 | T8: TRUE | U8: FALSE | V8: 0 | W8: 0
A9: f72ac231-6a87-43ef-b01d-60f1ba670cc9 | B9: (name not on file) | C9: 46057 | D9: 2026-02 | E9: TRUE | F9: TRUE | G9: TRUE | H9: TRUE | I9: TRUE | J9: FALSE | K9: TRUE | L9: TRUE | M9: TRUE | N9: TRUE | O9: 15 | P9: 1 | Q9: 14 | S9: 46063 | T9: TRUE | U9: FALSE | V9: 2 | W9: 246
A10: 67e3523d-dff6-47d4-bebf-55bba69ef991 | B10: ponceluxe laser studio | C10: 46058 | D10: 2026-02 | E10: TRUE | F10: TRUE | G10: TRUE | H10: TRUE | I10: TRUE | J10: FALSE | K10: TRUE | L10: TRUE | M10: TRUE | N10: TRUE | O10: 434 | P10: 55 | Q10: 379 | S10: 46237 | T10: TRUE | U10: TRUE | V10: 1 | W10: 3500 | X10: AzZkqoV5Dtkn82au8 | Y10: 100 | Z10: active
A11: f774f9a1-e3df-458b-949f-a1cd9a346214 | B11: Jeans lash lounge | C11: 46059 | D11: 2026-02 | E11: TRUE | F11: TRUE | G11: TRUE | H11: TRUE | I11: TRUE | J11: TRUE | K11: FALSE | L11: TRUE | M11: TRUE | N11: TRUE | O11: 24 | P11: 22 | Q11: 2 | S11: 46223 | T11: TRUE | U11: TRUE | V11: 0 | W11: 0 | X11: AzqKGMUj2VY405ZFf | Y11: 399 | Z11: active
A12: 8516a713-7500-4ad6-9dde-d49f249abbb4 | B12: Lord of Locs | C12: 46062 | D12: 2026-02 | E12: TRUE | F12: TRUE | G12: TRUE | H12: TRUE | I12: TRUE | J12: TRUE | K12: TRUE | L12: TRUE | M12: TRUE | N12: TRUE | O12: 77 | P12: 67 | Q12: 10 | S12: 46237 | T12: TRUE | U12: TRUE | V12: 72 | W12: 3956 | X12: cus_Q0yzaP9rDqi7TT | Y12: 150 | Z12: active
A13: db2e88b9-af6a-4d47-8900-9fcca27925a9 | B13: The Beauty Bar Salon and Spa | C13: 46062 | D13: 2026-02 | E13: TRUE | F13: TRUE | G13: TRUE | H13: TRUE | I13: TRUE | J13: TRUE | K13: FALSE | L13: TRUE | M13: TRUE | N13: TRUE | O13: 459 | P13: 415 | Q13: 44 | S13: 46237 | T13: TRUE | U13: TRUE | V13: 271 | W13: 8558.5 | X13: cus_OUyjtBRaU7IAeF | Y13: 162.94 | Z13: active
A14: ccf27c15-8215-40aa-8204-aa7573903d30 | B14: Premium African Braids | C14: 46063 | D14: 2026-02 | E14: TRUE | F14: TRUE | G14: TRUE | H14: TRUE | I14: TRUE | J14: TRUE | K14: FALSE | L14: TRUE | M14: TRUE | N14: TRUE | O14: 7 | P14: 6 | Q14: 1 | S14: 46172 | T14: TRUE | U14: FALSE | V14: 0 | W14: 0 | X14: cus_RR29SxTsdXcDRw | Y14: 108.62 | Z14: active
A15: b5974616-7dcd-4f9f-91f7-d27f886d343d | B15: (name not on file) | C15: 46064 | D15: 2026-02 | E15: TRUE | F15: TRUE | G15: TRUE | H15: TRUE | I15: TRUE | J15: FALSE | K15: TRUE | L15: TRUE | M15: TRUE | N15: TRUE | O15: 1 | P15: 1 | Q15: 0 | S15: 46064 | T15: TRUE | U15: FALSE | V15: 0 | W15: 0
A16: 07a8e1fa-f005-4cf5-9182-f1d48d82fa2e | B16: Emporio African Braids | C16: 46065 | D16: 2026-02 | E16: TRUE | F16: TRUE | G16: TRUE | H16: TRUE | I16: TRUE | J16: TRUE | K16: FALSE | L16: TRUE | M16: TRUE | N16: TRUE | O16: 67 | P16: 57 | Q16: 10 | S16: 46237 | T16: TRUE | U16: TRUE | V16: 40 | W16: 1803.6 | X16: cus_Q7pV871MpzSuGB | Y16: 50 | Z16: active
A17: 4ebee20a-db99-4e09-b3f0-afa88cb49861 | B17: Adel braids | C17: 46066 | D17: 2026-02 | E17: TRUE | F17: TRUE | G17: TRUE | H17: TRUE | I17: TRUE | J17: TRUE | K17: FALSE | L17: TRUE | M17: TRUE | N17: TRUE | O17: 19 | P17: 17 | Q17: 2 | S17: 46220 | T17: TRUE | U17: TRUE | V17: 9 | W17: 396 | X17: AzqH9DV2H2LEsW8T | Y17: 199 | Z17: active
A18: 2223edcb-30e6-4131-ad63-42d5a3b2d50f | B18: (name not on file) | C18: 46066 | D18: 2026-02 | E18: TRUE | F18: TRUE | G18: TRUE | H18: TRUE | I18: TRUE | J18: FALSE | K18: TRUE | L18: TRUE | M18: TRUE | N18: TRUE | O18: 8 | P18: 8 | Q18: 0 | S18: 46067 | T18: TRUE | U18: FALSE | V18: 1 | W18: 90
A19: 383a7fdd-b410-414b-a3db-82c1774616fb | B19: Hair By Camille | C19: 46070 | D19: 2026-02 | E19: TRUE | F19: TRUE | G19: TRUE | H19: TRUE | I19: TRUE | J19: TRUE | K19: FALSE | L19: TRUE | M19: TRUE | N19: TRUE | O19: 192 | P19: 48 | Q19: 65 | S19: 46237 | T19: TRUE | U19: TRUE | V19: 0 | W19: 0 | X19: cus_RiJ2uhBiBlg9ZH | Y19: 179 | Z19: active
A20: 3be18092-1615-4c48-915c-f83e8ba38950 | B20: (name not on file) | C20: 46071 | D20: 2026-02 | E20: TRUE | F20: TRUE | G20: TRUE | H20: TRUE | I20: TRUE | J20: FALSE | K20: TRUE | L20: TRUE | M20: TRUE | N20: TRUE | O20: 3 | P20: 3 | Q20: 0 | S20: 46071 | T20: TRUE | U20: FALSE | V20: 0 | W20: 0
A21: cee7df4b-ba3b-43df-858d-9304187b4723 | B21: (name not on file) | C21: 46072 | D21: 2026-02 | E21: TRUE | F21: TRUE | G21: TRUE | H21: TRUE | I21: TRUE | J21: FALSE | K21: TRUE | L21: TRUE | M21: TRUE | N21: TRUE | O21: 2 | P21: 2 | Q21: 0 | S21: 46073 | T21: TRUE | U21: FALSE | V21: 0 | W21: 0
A22: fa2619ea-5509-4815-8b9e-a933e26321bf | B22: (name not on file) | C22: 46073 | D22: 2026-02 | E22: TRUE | F22: TRUE | G22: TRUE | H22: TRUE | I22: TRUE | J22: FALSE | K22: TRUE | L22: TRUE | M22: TRUE | N22: TRUE | O22: 0 | P22: 0 | Q22: 0 | T22: FALSE | U22: FALSE | V22: 0 | W22: 0
A23: 54a27121-0b23-4ed0-9153-aec06840a7f7 | B23: it's Waxing & Threading | C23: 46074 | D23: 2026-02 | E23: TRUE | F23: TRUE | G23: TRUE | H23: TRUE | I23: TRUE | J23: FALSE | K23: TRUE | L23: TRUE | M23: TRUE | N23: TRUE | O23: 106 | P23: 76 | Q23: 30 | S23: 46235 | T23: TRUE | U23: TRUE | V23: 14 | W23: 903 | X23: 16AflPVAZLsIpMXS4 | Y23: 1250.07 | Z23: active
A24: 11e81849-6bde-4d33-855d-927f443698bd | B24: Miracle hands braiding Studio | C24: 46077 | D24: 2026-02 | E24: TRUE | F24: TRUE | G24: TRUE | H24: TRUE | I24: TRUE | J24: FALSE | K24: TRUE | L24: TRUE | M24: TRUE | N24: TRUE | O24: 52 | P24: 33 | Q24: 19 | S24: 46237 | T24: TRUE | U24: TRUE | V24: 0 | W24: 0 | X24: cus_PU3NzApnWkMxob | Y24: 150 | Z24: active
A25: 1b26e354-eb83-433b-a77c-7f2b3f9355f3 | B25: (name not on file) | C25: 46078 | D25: 2026-02 | E25: TRUE | F25: TRUE | G25: TRUE | H25: TRUE | I25: TRUE | J25: FALSE | K25: TRUE | L25: TRUE | M25: TRUE | N25: TRUE | O25: 21 | P25: 21 | Q25: 0 | S25: 46079 | T25: TRUE | U25: FALSE | V25: 0 | W25: 0
A26: bdcb9096-7934-440c-bc24-57268f63b08b | B26: Vida Beauty Bar | C26: 46078 | D26: 2026-02 | E26: TRUE | F26: TRUE | G26: TRUE | H26: TRUE | I26: TRUE | J26: FALSE | K26: TRUE | L26: TRUE | M26: TRUE | N26: TRUE | O26: 694 | P26: 191 | Q26: 503 | S26: 46237 | T26: TRUE | U26: TRUE | V26: 0 | W26: 0 | X26: 16BXdwUvalf4c3pdW | Y26: 199 | Z26: active
A27: 3a38f3a3-b66e-4f62-b841-3e9ce14350ad | B27: Golden Hair Braiding | C27: 46079 | D27: 2026-02 | E27: TRUE | F27: TRUE | G27: TRUE | H27: TRUE | I27: TRUE | J27: FALSE | K27: TRUE | L27: TRUE | M27: TRUE | N27: TRUE | O27: 128 | P27: 128 | Q27: 0 | S27: 46234 | T27: TRUE | U27: TRUE | V27: 0 | W27: 0 | X27: AzqO4bV13axpA8JbC | Y27: 200 | Z27: active
A28: 04d19914-49c8-44f2-b251-5fbd643a2300 | B28: Jamila African Hair Braiding | C28: 46079 | D28: 2026-02 | E28: TRUE | F28: TRUE | G28: TRUE | H28: TRUE | I28: TRUE | J28: FALSE | K28: TRUE | L28: TRUE | M28: TRUE | N28: TRUE | O28: 114 | P28: 114 | Q28: 0 | S28: 46237 | T28: TRUE | U28: TRUE | V28: 0 | W28: 0 | X28: AzqbodV0xNjaWDWp0 | Y28: 150 | Z28: active
A29: 65dd98d3-43be-49f3-93f4-ef35117d66b3 | B29: (name not on file) | C29: 46080 | D29: 2026-02 | E29: TRUE | F29: TRUE | G29: TRUE | H29: TRUE | I29: TRUE | J29: FALSE | K29: TRUE | L29: TRUE | M29: TRUE | N29: TRUE | O29: 14 | P29: 14 | Q29: 0 | S29: 46083 | T29: TRUE | U29: FALSE | V29: 1 | W29: 55
A30: 059e2eba-670d-4618-bd84-63b3a685bad1 | B30: Naomi's African Hair Braiding Salon | C30: 46080 | D30: 2026-02 | E30: TRUE | F30: TRUE | G30: TRUE | H30: TRUE | I30: TRUE | J30: FALSE | K30: FALSE | L30: FALSE | M30: FALSE | N30: FALSE | O30: 0 | P30: 0 | Q30: 0 | T30: FALSE | U30: FALSE | V30: 0 | W30: 0 | X30: cus_PjQE46ZlgRsQvY | Y30: 100 | Z30: active
A31: b7c19608-d68c-4f1d-860d-ff6f70d4a564 | B31: The Moon Beauty | Facial Spa | C31: 46083 | D31: 2026-03 | E31: TRUE | F31: TRUE | G31: FALSE | H31: FALSE | I31: FALSE | J31: FALSE | K31: FALSE | L31: FALSE | M31: FALSE | N31: FALSE | O31: 0 | P31: 0 | Q31: 0 | T31: FALSE | U31: FALSE | V31: 0 | W31: 0 | X31: cus_Q265iKOdiQIKnz | Y31: 200 | Z31: active
A32: 7c02b584-78b6-4c2e-b105-a8f6f51ad7f7 | B32: The Sculpt Spa | C32: 46083 | D32: 2026-03 | E32: TRUE | F32: TRUE | G32: TRUE | H32: TRUE | I32: TRUE | J32: TRUE | K32: FALSE | L32: TRUE | M32: TRUE | N32: TRUE | O32: 6 | P32: 6 | Q32: 0 | S32: 46199 | T32: TRUE | U32: FALSE | V32: 0 | W32: 0 | X32: cus_U3eC0paE9t3LVN | Y32: 150 | Z32: active
A33: 6d08968b-164f-49ed-8832-0e7590d22863 | B33: (name not on file) | C33: 46084 | D33: 2026-03 | E33: TRUE | F33: TRUE | G33: TRUE | H33: TRUE | I33: TRUE | J33: FALSE | K33: TRUE | L33: TRUE | M33: TRUE | N33: TRUE | O33: 21 | P33: 21 | Q33: 0 | S33: 46087 | T33: TRUE | U33: FALSE | V33: 3 | W33: 285.5
A34: ba888c97-7ef0-458b-9509-f43966d256aa | B34: Kindness Massage | C34: 46086 | D34: 2026-03 | E34: TRUE | F34: TRUE | G34: TRUE | H34: TRUE | I34: TRUE | J34: TRUE | K34: FALSE | L34: TRUE | M34: TRUE | N34: TRUE | O34: 164 | P34: 103 | Q34: 61 | S34: 46236 | T34: TRUE | U34: TRUE | V34: 0 | W34: 0 | X34: 169m4nUy2hjFi1Vuz | Y34: 248 | Z34: active
A35: 78303b7a-d9cd-4399-a2a0-7fe3324fc2a7 | B35: Flawless Face & Wax by Felecia | C35: 46086 | D35: 2026-03 | E35: TRUE | F35: TRUE | G35: TRUE | H35: TRUE | I35: TRUE | J35: FALSE | K35: FALSE | L35: FALSE | M35: FALSE | N35: FALSE | O35: 0 | P35: 0 | Q35: 0 | T35: FALSE | U35: FALSE | V35: 0 | W35: 0
A36: b105cf01-8be7-4c7e-a158-c9e4deb10a1d | B36: Heavenly Touch by Donna | C36: 46086 | D36: 2026-03 | E36: TRUE | F36: TRUE | G36: TRUE | H36: TRUE | I36: TRUE | J36: TRUE | K36: FALSE | L36: TRUE | M36: TRUE | N36: TRUE | O36: 32 | P36: 8 | Q36: 24 | S36: 46237 | T36: TRUE | U36: TRUE | V36: 0 | W36: 0 | X36: 16BcgdV2pu06pjj0 | Y36: 199 | Z36: active
A37: c2df4b6a-2c1d-4a33-bc7c-af3af4d1fcce | B37: Charlotte African hair braiding | C37: 46087 | D37: 2026-03 | E37: TRUE | F37: TRUE | G37: TRUE | H37: TRUE | I37: TRUE | J37: FALSE | K37: FALSE | L37: FALSE | M37: FALSE | N37: FALSE | O37: 0 | P37: 0 | Q37: 0 | T37: FALSE | U37: FALSE | V37: 0 | W37: 0 | X37: cus_P9D8q6qIZmvzmr | Y37: 90 | Z37: active
A38: 1a594d9e-0d13-4235-9ff7-69e8a4ac1a5b | B38: (name not on file) | C38: 46092 | D38: 2026-03 | E38: TRUE | F38: TRUE | G38: TRUE | H38: TRUE | I38: TRUE | J38: FALSE | K38: TRUE | L38: TRUE | M38: TRUE | N38: TRUE | O38: 0 | P38: 0 | Q38: 0 | T38: FALSE | U38: FALSE | V38: 0 | W38: 0
A39: e3dc5b9f-56fa-4ee4-a974-84f4dfabed48 | B39: African Hair Braiding by Hawa | C39: 46092 | D39: 2026-03 | E39: TRUE | F39: TRUE | G39: TRUE | H39: TRUE | I39: TRUE | J39: TRUE | K39: FALSE | L39: TRUE | M39: TRUE | N39: TRUE | O39: 17 | P39: 17 | Q39: 0 | S39: 46230 | T39: TRUE | U39: TRUE | V39: 17 | W39: 540 | X39: 16CKWJUpdCJRi1kZB | Y39: 100 | Z39: active
A40: 12d1230a-7f02-467f-b32c-ccefbe2d268a | B40: ChinnysFlair | C40: 46092 | D40: 2026-03 | E40: TRUE | F40: TRUE | G40: TRUE | H40: TRUE | I40: TRUE | J40: FALSE | K40: TRUE | L40: TRUE | M40: TRUE | N40: TRUE | O40: 33 | P40: 25 | Q40: 8 | S40: 46233 | T40: TRUE | U40: TRUE | V40: 4 | W40: 687.5 | X40: 169z91UzihO0y1liT | Y40: 199 | Z40: active
...

Sheet Cohort Retention
A1: Cohort retention — 178 legitimate locations
A2: Same definitions as Adoption Funnel; TOTAL reconciles to it exactly.
A4: Cohort | B4: Entered | C4: Enabled (flag) | D4: Operationally live | E4: Live in last 30d | F4: % of op. live still live
A5: 2026-01 | B5: =SUMPRODUCT(--(Locations!$D$2:$D$179=$A5)) | C5: =SUMPRODUCT(--(Locations!$D$2:$D$179=$A5),--(Locations!$M$2:$M$179=TRUE)) | D5: =SUMPRODUCT(--(Locations!$D$2:$D$179=$A5),--(Locations!$T$2:$T$179=TRUE)) | E5: =SUMPRODUCT(--(Locations!$D$2:$D$179=$A5),--(Locations!$S$2:$S$179>=Summary!$B$3-30)) | F5: =IFERROR(E5/D5,0)
A6: 2026-02 | B6: =SUMPRODUCT(--(Locations!$D$2:$D$179=$A6)) | C6: =SUMPRODUCT(--(Locations!$D$2:$D$179=$A6),--(Locations!$M$2:$M$179=TRUE)) | D6: =SUMPRODUCT(--(Locations!$D$2:$D$179=$A6),--(Locations!$T$2:$T$179=TRUE)) | E6: =SUMPRODUCT(--(Locations!$D$2:$D$179=$A6),--(Locations!$S$2:$S$179>=Summary!$B$3-30)) | F6: =IFERROR(E6/D6,0)
A7: 2026-03 | B7: =SUMPRODUCT(--(Locations!$D$2:$D$179=$A7)) | C7: =SUMPRODUCT(--(Locations!$D$2:$D$179=$A7),--(Locations!$M$2:$M$179=TRUE)) | D7: =SUMPRODUCT(--(Locations!$D$2:$D$179=$A7),--(Locations!$T$2:$T$179=TRUE)) | E7: =SUMPRODUCT(--(Locations!$D$2:$D$179=$A7),--(Locations!$S$2:$S$179>=Summary!$B$3-30)) | F7: =IFERROR(E7/D7,0)
A8: 2026-04 | B8: =SUMPRODUCT(--(Locations!$D$2:$D$179=$A8)) | C8: =SUMPRODUCT(--(Locations!$D$2:$D$179=$A8),--(Locations!$M$2:$M$179=TRUE)) | D8: =SUMPRODUCT(--(Locations!$D$2:$D$179=$A8),--(Locations!$T$2:$T$179=TRUE)) | E8: =SUMPRODUCT(--(Locations!$D$2:$D$179=$A8),--(Locations!$S$2:$S$179>=Summary!$B$3-30)) | F8: =IFERROR(E8/D8,0)
A9: 2026-05 | B9: =SUMPRODUCT(--(Locations!$D$2:$D$179=$A9)) | C9: =SUMPRODUCT(--(Locations!$D$2:$D$179=$A9),--(Locations!$M$2:$M$179=TRUE)) | D9: =SUMPRODUCT(--(Locations!$D$2:$D$179=$A9),--(Locations!$T$2:$T$179=TRUE)) | E9: =SUMPRODUCT(--(Locations!$D$2:$D$179=$A9),--(Locations!$S$2:$S$179>=Summary!$B$3-30)) | F9: =IFERROR(E9/D9,0)
A10: 2026-06 | B10: =SUMPRODUCT(--(Locations!$D$2:$D$179=$A10)) | C10: =SUMPRODUCT(--(Locations!$D$2:$D$179=$A10),--(Locations!$M$2:$M$179=TRUE)) | D10: =SUMPRODUCT(--(Locations!$D$2:$D$179=$A10),--(Locations!$T$2:$T$179=TRUE)) | E10: =SUMPRODUCT(--(Locations!$D$2:$D$179=$A10),--(Locations!$S$2:$S$179>=Summary!$B$3-30)) | F10: =IFERROR(E10/D10,0)
A11: 2026-07 | B11: =SUMPRODUCT(--(Locations!$D$2:$D$179=$A11)) | C11: =SUMPRODUCT(--(Locations!$D$2:$D$179=$A11),--(Locations!$M$2:$M$179=TRUE)) | D11: =SUMPRODUCT(--(Locations!$D$2:$D$179=$A11),--(Locations!$T$2:$T$179=TRUE)) | E11: =SUMPRODUCT(--(Locations!$D$2:$D$179=$A11),--(Locations!$S$2:$S$179>=Summary!$B$3-30)) | F11: =IFERROR(E11/D11,0)
A12: 2026-08 | B12: =SUMPRODUCT(--(Locations!$D$2:$D$179=$A12)) | C12: =SUMPRODUCT(--(Locations!$D$2:$D$179=$A12),--(Locations!$M$2:$M$179=TRUE)) | D12: =SUMPRODUCT(--(Locations!$D$2:$D$179=$A12),--(Locations!$T$2:$T$179=TRUE)) | E12: =SUMPRODUCT(--(Locations!$D$2:$D$179=$A12),--(Locations!$S$2:$S$179>=Summary!$B$3-30)) | F12: =IFERROR(E12/D12,0)
A13: TOTAL | B13: =SUM(B5:B12) | C13: =SUM(C5:C12) | D13: =SUM(D5:D12) | E13: =SUM(E5:E12) | F13: =IFERROR(E13/D13,0)

Sheet Bookings and Revenue
A1: Bookings, payments and displaced incumbents
A2: Booking figures use the 'earned' definition. v1 used migration_source IS NULL alone and overstated volume ~2.4x.
A4: Metric | B4: Value | C4: What it is
A5: Earned bookings since launch | B5: =SUM(Locations!$O$2:$O$445) | C5: created 30/01/26 to as-of, no migration tag
A6: Customer-made bookings | B6: =SUM(Locations!$P$2:$P$445) | C6: created_by_type EC or CLIENT — proves demand
A7: Staff-made bookings | B7: =SUM(Locations!$Q$2:$Q$445) | C7: created_by_type SP
A8: Pre-launch untagged (EXCLUDED) | B8: =SUM(Locations!$R$2:$R$445) | C8: imported history with no migration_source
A9: Tagged migration (EXCLUDED) | B9: =SUM(Locations!$S$2:$S$445) | C9: explicitly flagged imports
A10: Future-dated (EXCLUDED) | B10: =SUM(Locations!$T$2:$T$445) | C10: impossible created_at values
A11: Value processed (USD) | B11: =SUM(Locations!$AA$2:$AA$445) | C11: completed payments created on/after 30/01/26
A12: Locations that processed a payment | B12: =SUMPRODUCT(--(Locations!$Z$2:$Z$445>0))
A14: All-entity totals (whole scheduling.* schema): 9,605 earned bookings · 4,627 customer-made · $328,021 completed payments POST-LAUNCH across 139 accounts. All-time completed payments are $646,104, but $318,083 of that predates the 30/01/26 launch and must not be presented as product value. Live database, queried 04/08/26.
A16: INCUMBENT SYSTEMS MIGRATED FROM
A17: Hardcoded. Source: scheduling.bookings.migration_source, 03/08/26. Only 14 accounts imported history — the rest had nothing to move or never fully switched.
A18: Prior system | B18: Bookings migrated | C18: Accounts
A19: Zoca internal ops | B19: 15756 | C19: 2
A20: Square | B20: 7748 | C20: 4
A21: Vagaro | B21: 6321 | C21: 1
A22: Fresha | B22: 4984 | C22: 1
A23: Booksy | B23: 4088 | C23: 1
A24: GlossGenius | B24: 3978 | C24: 1
A25: Acuity | B25: 3338 | C25: 4
A26: Setmore | B26: 1158 | C26: 1
A27: GoDaddy | B27: 56 | C27: 2

Sheet Objection Themes
A1: Why accounts did not convert
A2: Mechanical evidence is proven by the funnel. Stated evidence is directional only and cannot be counted per account.
A4: MECHANICAL — proven
A5: Finding | B5: Value | C5: Why it matters
A6: Locations that skipped payment setup | B6: =SUMPRODUCT(--(Locations!$K$2:$K$445=TRUE)) | C6: No deposits, no no-show fees. Without payments it is a diary, and a diary loses to the incumbent.
A7: Locations that configured payments | B7: =SUMPRODUCT(--(Locations!$J$2:$J$445=TRUE))
A8: Enabled (flag) but never earned a booking | B8: =SUMPRODUCT(--(Locations!$M$2:$M$445=TRUE),--(Locations!$O$2:$O$445=0)) | C8: Completed every setup step, then nothing. Setup completion is being mistaken for adoption.
A9: Operationally live but dormant 30d+ | B9: =SUMPRODUCT(--(Locations!$X$2:$X$445=TRUE),--(Locations!$W$2:$W$445<Summary!$B$3-30)) | C9: The core retention problem
A10: Locations that imported from a rival | B10: =SUMPRODUCT(--(Locations!$U$2:$U$445<>"")) | C10: Very few actually moved their history across.
A13: STATED — topic prevalence across 1,829 scheduling calls, 01/11/25 to 03/08/26
A14: Hardcoded. Regex over sales.fireflies_meeting.summary. CAUTION: these calls carry no usable entity_id, so these CANNOT be counted per account. Never present as 'N accounts said X'. Counts are topic prevalence only and were NOT re-audited for the word-boundary defect — treat as indicative.
A15: Topic | B15: Calls | C15: Share of 1,829 | D15: Comment
A16: Deferred / 'not right now' | B16: 441 | C16: =B16/1829
A17: Migration or data-transfer effort | B17: 247 | C17: =B17/1829
A18: Payments, deposits, no-show fees | B18: 227 | C18: =B18/1829 | D18: Matches the mechanical finding
A19: Contract / lock-in language | B19: 215 | C19: =B19/1829 | D19: Noisy
A20: Named an incumbent competitor | B20: 303 | C20: =B20/1829 | D20: The reliable signal
A21: Explicit refusal language | B21: 174 | C21: =B21/1829
A22: Prefers phone / walk-in / manual | B22: 119 | C22: =B22/1829
A23: Price or budget | B23: 69 | C23: =B23/1829
A24: Staff resistance or complexity | B24: 42 | C24: =B24/1829
A26: Incumbents named (validated 04/08/26 with word boundaries): Square 101 in genuine product context — NOT the 269 originally reported, which matched non-product uses of the word. Vagaro 105 and Acuity 26 verified clean (bounded = unbounded). Booksy 46 · Mindbody 39 · Fresha 35 · StyleSeat 11 · GlossGenius 11 · other 43 — not individually re-audited.
A28: VERIFIED BY READING CALL EXCERPTS BY HAND
A29: • Feature gaps keep the old system alive — staff revenue and commission reporting, clock-in/out, staff permission levels, calendar column-per-staff view, selective client blocking, package and membership migration, intake forms.
A30: • Payment processor economics — Stripe rates raised as a negotiation point rather than accepted.
A31: • Base subscription price — $149/month cited as unaffordable by an account under budget freeze; a whole-platform objection, not a scheduling one.
A32: • Rollback on confusion — at least one account asked for the booking system to be revoked 'to reduce confusion and inefficiency' after enabling it.
A33: • Free is the wedge that works — where the pitch replaces a paid incumbent at no cost, it lands.

Sheet Data Quality
A1: Data quality — defects in the source data itself
A2: Read this before trusting any booking count, here or anywhere else in Zoca reporting.
A4: Defect | B4: Scale | C4: Consequence | D4: Handling in v2
A5: Imported history carries no migration_source tag | B5: =SUM(Locations!$R$2:$R$445) | C5: 33 entities' pre-launch bookings look organic. v1 counted them as earned and overstated volume ~2.4x. | D5: Excluded: earned bookings require created_at >= 30/01/26
A6: Future-dated created_at values | B6: =SUM(Locations!$T$2:$T$445) | C6: Bookings created in 2027. They automatically satisfy any 'last 30 days' test. | D6: Excluded: earned bookings require created_at <= as-of
A7: is_scheduling_enabled is unreliable | B7: =SUMPRODUCT(--(Locations!$M$2:$M$445=FALSE),--(Locations!$O$2:$O$445>0)) | C7: Locations take real bookings while flagged FALSE (all also show onboarding_completed FALSE). | D7: Reported separately as 'Operationally live'
A8: Duplicate Chargebee customer records | B8: 89 | C8: 2,026 records hold 1,799 distinct emails. Counting customer_id over-counts businesses. | D8: All account counts resolve to entity_id first
A9: scheduling.onboarding has two entity ids | B9: — | C9: entity_id = parent business (joins entities.businesses); location_entity_id = the location (joins bookings, Chargebee, GBP). Joining on the wrong one returns zero rows and no error. | D9: location_entity_id used throughout
A10: Fireflies entity_id is 1.9% populated | B10: — | C10: Calls cannot be joined to accounts directly. | D10: Attribution via participants email → chargebee.customers.email
A11: cx.open_issues / cx.churn_potential stopped writing 14/01/26 | B11: — | C11: Two account-health tables went dark two weeks before scheduling launched, so there is no qualitative feed for the rollout period. | D11: Not used; flagged for investigation
